Workbook
Name flag_pin_historical: #REF!
Name flag_pin_perc: #REF!
Name perc_1st_2nd: #REF!
Name perc_1st_3rd: #REF!
Name pin_perc: 'PiN Visuals'!$B$5:$F$16
Name sectors_sev_4: #REF!
Name sectors_sev_5: #REF!
Name zero_pin_thresh: #REF!

Sheet WS - 3.1 Overall PiN
R1: 5929291.6 | T1: 2606169 | U1: 1849891
A2: Location | E2: Populaton | G2: Sectoral PiN (Number)
A3: Admin 1 | B3: Admin 1 P-Code | C3: Admin 2 | D3: Admin 2 P-Code | E3: Population | F3: Population Group | G3: CCCM | H3: Education | I3: Early Recovery | J3: Food Security | K3: Heath | L3: Nutrition | M3: Overarching Protection | N3: Shelter | O3: WASH | P3: Severity | Q3: Preliminary PiN | R3: Final PiN | S3: Evidence & Comments | T3: Targeted | U3: Priority
A4: Adamawa | B4: NG002 | C4: Demsa | D4: NG002001 | E4: 285016 | G4: 16908 | H4: 18581 | I4: 0 | J4: 77315.095 | K4: 49898.766 | L4: 68632 | M4: 7510 | N4: 20943 | O4: 57504.497 | P4: 3 | Q4: 77315.095 | R4: 77315.095 | T4: 0 | U4: 0
A5: Adamawa | B5: NG002 | C5: Fufore | D5: NG002002 | E5: 443009 | G5: 7710 | H5: 40636.214 | I5: 0 | J5: 94554.224 | K5: 79161.571 | M5: 0 | N5: 40357 | O5: 0 | P5: 2 | Q5: 0 | R5: 0 | T5: 0 | U5: 0
A6: Adamawa | B6: NG002 | C6: Ganye | D6: NG002003 | E6: 310190 | G6: 816 | H6: 27494.619 | I6: 0 | J6: 70580.505 | K6: 54245.604 | M6: 0 | N6: 23503 | O6: 0 | P6: 2 | Q6: 0 | R6: 0 | T6: 0 | U6: 0
A7: Adamawa | B7: NG002 | C7: Girei | D7: NG002004 | E7: 250604 | G7: 17192 | H7: 14100 | I7: 0 | J7: 62463.544 | K7: 49550.509 | L7: 60345 | M7: 7708 | N7: 24854 | O7: 52301.023 | P7: 3 | Q7: 62463.544 | R7: 62463.544 | T7: 0 | U7: 0
A8: Adamawa | B8: NG002 | C8: Gombi | D8: NG002005 | E8: 290858 | G8: 4581 | H8: 14642 | I8: 0 | J8: 61376.852 | K8: 63849.537 | L8: 64018 | M8: 0 | N8: 87632 | O8: 101676.93 | P8: 3 | Q8: 101676.93 | R8: 101676.93 | T8: 0 | U8: 0
A9: Adamawa | B9: NG002 | C9: Guyuk | D9: NG002006 | E9: 251727 | G9: 4314 | H9: 14882 | I9: 0 | J9: 86052.284 | K9: 46823.496 | L9: 60616 | M9: 594 | N9: 15467 | O9: 35242.812 | P9: 3 | Q9: 86052.284 | R9: 86052.284 | T9: 0 | U9: 0
A10: Adamawa | B10: NG002 | C10: Hong | D10: NG002007 | E10: 304190 | G10: 5795 | H10: 18883 | I10: 0 | J10: 55536.322 | K10: 78482.654 | M10: 0 | N10: 91553 | O10: 0 | P10: 2 | Q10: 0 | R10: 0 | T10: 0 | U10: 0
A11: Adamawa | B11: NG002 | C11: Jada | D11: NG002008 | E11: 315353 | G11: 866 | H11: 20809 | I11: 0 | J11: 69956.476 | K11: 55160.666 | M11: 0 | N11: 10627 | O11: 0 | P11: 2 | Q11: 0 | R11: 0 | T11: 0 | U11: 0
A12: Adamawa | B12: NG002 | C12: Lamurde | D12: NG002009 | E12: 197983 | G12: 3720 | H12: 14017 | I12: 0 | J12: 52231.107 | K12: 24944.114 | M12: 0 | N12: 39526 | O12: 0 | P12: 2 | Q12: 0 | R12: 0 | T12: 0 | U12: 0
A13: Adamawa | B13: NG002 | C13: Madagali | D13: NG002010 | E13: 245471 | G13: 14747 | H13: 21430.667 | I13: 0 | J13: 109810.2 | K13: 47825.646 | L13: 54028 | M13: 79396 | N13: 38331 | O13: 71125.735 | P13: 3 | Q13: 109810.2 | R13: 109810.2 | T13: 0 | U13: 0
A14: Adamawa | B14: NG002 | C14: Maiha | D14: NG002011 | E14: 188095 | G14: 14065 | H14: 8377 | I14: 0 | J14: 45756.532 | K14: 40032.311 | M14: 86666 | N14: 76878 | O14: 0 | P14: 2 | Q14: 0 | R14: 0 | T14: 0 | U14: 0
A15: Adamawa | B15: NG002 | C15: Mayo-Belwa | D15: NG002012 | E15: 313081 | G15: 1305 | H15: 19942 | I15: 0 | J15: 66219.265 | K15: 23865.865 | M15: 0 | N15: 13167 | O15: 0 | P15: 2 | Q15: 0 | R15: 0 | T15: 0 | U15: 0
A16: Adamawa | B16: NG002 | C16: Michika | D16: NG002013 | E16: 262408 | G16: 3205 | H16: 22303.762 | I16: 0 | J16: 89699.075 | K16: 64988.825 | L16: 57756 | M16: 79118 | N16: 168368 | O16: 102210.87 | P16: 3 | Q16: 168368 | R16: 168368 | T16: 0 | U16: 0
A17: Adamawa | B17: NG002 | C17: Mubi North | D17: NG002014 | E17: 292264 | G17: 12927 | H17: 25749.548 | I17: 0 | J17: 54717.446 | K17: 52001.086 | L17: 64327 | M17: 37000 | N17: 109856 | O17: 48373.175 | P17: 3 | Q17: 109856 | R17: 109856 | T17: 0 | U17: 0
A18: Adamawa | B18: NG002 | C18: Mubi South | D18: NG002015 | E18: 266030 | G18: 7502 | H18: 16309 | I18: 0 | J18: 49278.36 | K18: 50100.378 | L18: 58553 | M18: 28717 | N18: 13154 | O18: 72722.011 | P18: 3 | Q18: 72722.011 | R18: 72722.011 | T18: 0 | U18: 0
A19: Adamawa | B19: NG002 | C19: Numan | D19: NG002016 | E19: 165015 | G19: 8750 | H19: 13728 | I19: 0 | J19: 38020.895 | K19: 34421.299 | L19: 39736 | M19: 12485 | N19: 18327 | O19: 57059.65 | P19: 3 | Q19: 57059.65 | R19: 57059.65 | T19: 0 | U19: 0
A20: Adamawa | B20: NG002 | C20: Shelleng | D20: NG002017 | E20: 248189 | G20: 10320 | H20: 22740.524 | I20: 0 | J20: 64350.003 | K20: 25316.08 | M20: 0 | N20: 72736 | O20: 0 | P20: 2 | Q20: 0 | R20: 0 | T20: 0 | U20: 0
A21: Adamawa | B21: NG002 | C21: Song | D21: NG002018 | E21: 381422 | G21: 5238 | H21: 26859 | I21: 0 | J21: 81062.901 | K21: 38893.983 | L21: 83951 | M21: 95866 | N21: 5105 | O21: 89978.748 | P21: 3 | Q21: 95866 | R21: 95866 | T21: 0 | U21: 0
A22: Adamawa | B22: NG002 | C22: Toungo | D22: NG002019 | E22: 101975 | G22: 566 | H22: 8943.0952 | I22: 0 | J22: 9421.8722 | K22: 7791.794 | M22: 0 | N22: 2028 | O22: 0 | P22: 2 | Q22: 0 | R22: 0 | T22: 0 | U22: 0
A23: Adamawa | B23: NG002 | C23: Yola North | D23: NG002020 | E23: 323370 | G23: 9091 | H23: 20978 | I23: 0 | J23: 93742.101 | K23: 44197.439 | M23: 0 | N23: 31722 | O23: 0 | P23: 2 | Q23: 0 | R23: 0 | T23: 0 | U23: 0
A24: Adamawa | B24: NG002 | C24: Yola South | D24: NG002021 | E24: 570233 | G24: 22010 | H24: 52892.071 | I24: 0 | J24: 67310.945 | K24: 51799.846 | L24: 137312 | M24: 115719 | N24: 21234 | O24: 58046.252 | P24: 2 | Q24: 0 | R24: 0 | T24: 0 | U24: 0
A25: Borno | B25: NG008 | C25: Abadam | D25: NG008001 | E25: 80385 | G25: 0 | H25: 19531.907 | I25: 0 | J25: 0 | K25: 5948.49 | M25: 0 | N25: 15997 | O25: 0 | P25: 2 | Q25: 0 | R25: 0 | S25: Inaccessable | T25: 0 | U25: 0
A26: Borno | B26: NG008 | C26: Askira/Uba | D26: NG008002 | E26: 245197 | G26: 11718 | H26: 33811.574 | I26: 0 | J26: 133609.19 | K26: 70259.544 | L26: 61471 | M26: 20963 | N26: 14201 | O26: 103007.35 | P26: 2 | Q26: 0 | R26: 0 | T26: 0 | U26: 0
A27: Borno | B27: NG008 | C27: Bama | D27: NG008003 | E27: 233112 | G27: 171239 | H27: 33720.098 | I27: 0 | J27: 102004.31 | K27: 92715.142 | L27: 71029 | M27: 112512 | N27: 99915 | O27: 210574.1 | P27: 3 | Q27: 210574.1 | R27: 210574.1 | T27: 0 | U27: 0
A28: Borno | B28: NG008 | C28: Bayo | D28: NG008004 | E28: 234872 | G28: 317 | H28: 34314.003 | I28: 0 | J28: 42780.338 | K28: 41384.198 | M28: 0 | N28: 4561 | O28: 0 | P28: 2 | Q28: 0 | R28: 0 | T28: 0 | U28: 0
A29: Borno | B29: NG008 | C29: Biu | D29: NG008005 | E29: 450926 | G29: 45579 | H29: 26473.503 | I29: 0 | J29: 138644.16 | K29: 95019.226 | L29: 107771 | M29: 45339 | N29: 14480 | O29: 76582.882 | P29: 3 | Q29: 138644.16 | R29: 138644.16 | T29: 0 | U29: 0
A30: Borno | B30: NG008 | C30: Chibok | D30: NG008006 | E30: 110736 | G30: 10200 | H30: 23770.612 | I30: 0 | J30: 41576.407 | K30: 28696.74 | L30: 26466 | M30: 0 | N30: 43098 | O30: 35899.07 | P30: 3 | Q30: 43098 | R30: 43098 | T30: 0 | U30: 0
A31: Borno | B31: NG008 | C31: Damboa | D31: NG008007 | E31: 176533 | G31: 110182 | H31: 28763.669 | I31: 0 | J31: 91060.754 | K31: 76040.266 | L31: 62210 | M31: 123635 | N31: 85993 | O31: 138366.62 | P31: 3 | Q31: 138366.62 | R31: 138366.62 | T31: 62210 | U31: 0
A32: Borno | B32: NG008 | C32: Dikwa | D32: NG008008 | E32: 139920 | G32: 107707 | H32: 24297.265 | I32: 0 | J32: 77097.991 | K32: 57042.706 | L32: 42634 | M32: 96963 | N32: 80210 | O32: 129855.1 | P32: 4 | Q32: 129855.1 | R32: 129855.1 | T32: 129855.1 | U32: 129855.1
A33: Borno | B33: NG008 | C33: Gubio | D33: NG008009 | E33: 206460 | G33: 12259 | H33: 31909.241 | I33: 0 | J33: 59180.7 | K33: 43969.225 | L33: 72757 | M33: 7999 | N33: 40278 | O33: 20762.693 | P33: 4 | Q33: 72757 | R33: 72757 | T33: 72757 | U33: 72757
A34: Borno | B34: NG008 | C34: Guzamala | D34: NG008010 | E34: 62747 | G34: 0 | H34: 17830.717 | I34: 0 | J34: 0 | K34: 10917.978 | L34: 17877 | M34: 18301 | N34: 10406 | O34: 18888.958 | P34: 3 | Q34: 18888.958 | S34: Inaccessable | T34: 0 | U34: 0
A35: Borno | B35: NG008 | C35: Gwoza | D35: NG008011 | E35: 267125 | G35: 163325 | H35: 33813.931 | I35: 0 | J35: 168833.71 | K35: 109359.71 | L35: 81393 | M35: 162436 | N35: 77779 | O35: 248053.2 | P35: 3 | Q35: 248053.2 | R35: 248053.2 | T35: 0 | U35: 0
A36: Borno | B36: NG008 | C36: Hawul | D36: NG008012 | E36: 253981 | G36: 22314 | H36: 33161.217 | I36: 0 | J36: 107298.64 | K36: 55027.878 | M36: 38477 | O36: 0 | P36: 2 | Q36: 0 | R36: 0 | T36: 0 | U36: 0
A37: Borno | B37: NG008 | C37: Jere | D37: NG008013 | E37: 866216 | G37: 268018 | H37: 89778.146 | I37: 0 | J37: 371984.38 | K37: 256338.27 | L37: 295899 | M37: 380993 | N37: 275829 | O37: 331485 | P37: 4 | Q37: 380993 | R37: 380993 | T37: 380993 | U37: 380993
A38: Borno | B38: NG008 | C38: Kaga | D38: NG008014 | E38: 116624 | G38: 24794 | H38: 23388.336 | I38: 0 | J38: 88329.088 | K38: 33298.255 | L38: 41098 | M38: 45093 | N38: 58957 | O38: 65760.273 | P38: 3 | Q38: 88329.088 | R38: 88329.088 | T38: 41098 | U38: 0
A39: Borno | B39: NG008 | C39: Kala/Balge | D39: NG008015 | E39: 40949 | G39: 40949 | H39: 15162.979 | I39: 0 | J39: 86622.986 | K39: 16911.937 | L39: 12477 | M39: 29663 | N39: 40949 | O39: 40842.4 | P39: 3 | Q39: 86622.986 | R39: 86622.986 | T39: 0 | U39: 0
A40: Borno | B40: NG008 | C40: Konduga | D40: NG008016 | E40: 270899 | G40: 88051 | H40: 33904.86 | I40: 0 | J40: 107855.41 | K40: 84218.427 | L40: 95465 | M40: 144148 | N40: 129679 | O40: 154287.42 | P40: 4 | Q40: 154287.42 | R40: 154287.42 | T40: 154287.42 | U40: 154287.42
...

Sheet PiN Visuals
P2: Select a sector: | Q2: Education
A5: Graph Bins | B5: {=TRANSPOSE(_xlfn.UNIQUE(tblPiNAnalysis[Population Group]))} -> 0 | H5: Graph Bins | I5: {=TRANSPOSE(_xlfn.UNIQUE(#REF!))} -> #REF!
A6: {=_xlfn._xlws.SORT(_xlfn.UNIQUE(INDEX(#REF!, 0, MATCH(_xlfn.CONCAT($Q$2, "%"), #REF!, 0))))} -> #REF! | B6: {=IF($A6="", "", IF(SUM(IF(INDEX(_xlfn._xlws.FILTER(#REF!, tblPiNAnalysis[Population Group]=B$5), 0, MATCH(_xlfn.CONCAT($Q$2, "%"), #REF!, 0))=$A6, 1, 0))=0, "",SUM(IF(INDEX(_xlfn._xlws.FILTER(#REF!, tblPiNAnalysis[Population Group]=B$5), 0, MATCH(_xlfn.CONCAT($Q$2, "%"), #REF!, 0))=$A6, 1, 0))))} -> #REF! | C6: {=IFERROR(IF(OR($A6="", C$5=""), "", IF(SUM(IF(INDEX(_xlfn._xlws.FILTER(#REF!, tblPiNAnalysis[Population Group]=C$5), 0, MATCH(_xlfn.CONCAT($Q$2, "%"), #REF!, 0))=$A6, 1, 0))=0, "",SUM(IF(INDEX(_xlfn._xlws.FILTER(#REF!, tblPiNAnalysis[Population Group]=C$5), 0, MATCH(_xlfn.CONCAT($Q$2, "%"), #REF!, 0))=$A6, 1, 0)))), "")} | D6: {=IFERROR(IF(OR($A6="", D$5=""), "", IF(SUM(IF(INDEX(_xlfn._xlws.FILTER(#REF!, tblPiNAnalysis[Population Group]=D$5), 0, MATCH(_xlfn.CONCAT($Q$2, "%"), #REF!, 0))=$A6, 1, 0))=0, "",SUM(IF(INDEX(_xlfn._xlws.FILTER(#REF!, tblPiNAnalysis[Population Group]=D$5), 0, MATCH(_xlfn.CONCAT($Q$2, "%"), #REF!, 0))=$A6, 1, 0)))), "")} | E6: {=IFERROR(IF(OR($A6="", E$5=""), "", IF(SUM(IF(INDEX(_xlfn._xlws.FILTER(#REF!, tblPiNAnalysis[Population Group]=E$5), 0, MATCH(_xlfn.CONCAT($Q$2, "%"), #REF!, 0))=$A6, 1, 0))=0, "",SUM(IF(INDEX(_xlfn._xlws.FILTER(#REF!, tblPiNAnalysis[Population Group]=E$5), 0, MATCH(_xlfn.CONCAT($Q$2, "%"), #REF!, 0))=$A6, 1, 0)))), "")} | F6: {=IFERROR(IF(OR($A6="", F$5=""), "", IF(SUM(IF(INDEX(_xlfn._xlws.FILTER(#REF!, tblPiNAnalysis[CCCM]=F$5), 0, MATCH(_xlfn.CONCAT($Q$2, "%"), #REF!, 0))=$A6, 1, 0))=0, "",SUM(IF(INDEX(_xlfn._xlws.FILTER(#REF!, tblPiNAnalysis[CCCM]=F$5), 0, MATCH(_xlfn.CONCAT($Q$2, "%"), #REF!, 0))=$A6, 1, 0)))), "")} | H6: {=_xlfn._xlws.SORT(_xlfn.UNIQUE(_xlfn._xlws.FILTER(INDEX(#REF!,0,MATCH($Q$2,#REF!,0)),INDEX(#REF!,0,MATCH($Q$2,#REF!,0))<=2)))} -> #REF! | I6: {=IF($H6="", "", IF($H6=2, SUM(IF(INDEX(_xlfn._xlws.FILTER(#REF!,#REF!= I$5), 0, MATCH($Q$2,#REF!, 0))>1.9, 1, 0)), IF(SUM(IF(INDEX(_xlfn._xlws.FILTER(#REF!,#REF!= I$5), 0, MATCH($Q$2,#REF!, 0))=$H6, 1, 0))=0, "", SUM(IF(INDEX(_xlfn._xlws.FILTER(#REF!,#REF!= I$5), 0, MATCH($Q$2,#REF!, 0))=$H6, 1, 0)))))} -> #REF! | J6: {=IFERROR(IF(OR($H6="", J5=""), "", IF($H6=2, SUM(IF(INDEX(_xlfn._xlws.FILTER(#REF!,#REF!= J$5), 0, MATCH($Q$2,#REF!, 0))>1.9, 1, 0)), IF(SUM(IF(INDEX(_xlfn._xlws.FILTER(#REF!,#REF!= J$5), 0, MATCH($Q$2,#REF!, 0))=$H6, 1, 0))=0, "", SUM(IF(INDEX(_xlfn._xlws.FILTER(#REF!,#REF!= J$5), 0, MATCH($Q$2,#REF!, 0))=$H6, 1, 0))))), "")} | K6: {=IFERROR(IF(OR($H6="", K5=""), "", IF($H6=2, SUM(IF(INDEX(_xlfn._xlws.FILTER(#REF!,#REF!= K$5), 0, MATCH($Q$2,#REF!, 0))>1.9, 1, 0)), IF(SUM(IF(INDEX(_xlfn._xlws.FILTER(#REF!,#REF!= K$5), 0, MATCH($Q$2,#REF!, 0))=$H6, 1, 0))=0, "", SUM(IF(INDEX(_xlfn._xlws.FILTER(#REF!,#REF!= K$5), 0, MATCH($Q$2,#REF!, 0))=$H6, 1, 0))))), "")} | L6: {=IFERROR(IF(OR($H6="", L5=""), "", IF($H6=2, SUM(IF(INDEX(_xlfn._xlws.FILTER(#REF!,#REF!= L$5), 0, MATCH($Q$2,#REF!, 0))>1.9, 1, 0)), IF(SUM(IF(INDEX(_xlfn._xlws.FILTER(#REF!,#REF!= L$5), 0, MATCH($Q$2,#REF!, 0))=$H6, 1, 0))=0, "", SUM(IF(INDEX(_xlfn._xlws.FILTER(#REF!,#REF!= L$5), 0, MATCH($Q$2,#REF!, 0))=$H6, 1, 0))))), "")} | M6: {=IFERROR(IF(OR($H6="", M5=""), "", IF($H6=2, SUM(IF(INDEX(_xlfn._xlws.FILTER(#REF!,#REF!= M$5), 0, MATCH($Q$2,#REF!, 0))>1.9, 1, 0)), IF(SUM(IF(INDEX(_xlfn._xlws.FILTER(#REF!,#REF!= M$5), 0, MATCH($Q$2,#REF!, 0))=$H6, 1, 0))=0, "", SUM(IF(INDEX(_xlfn._xlws.FILTER(#REF!,#REF!= M$5), 0, MATCH($Q$2,#REF!, 0))=$H6, 1, 0))))), "")}
B7: {=IF($A7="", "", IF(SUM(IF(INDEX(_xlfn._xlws.FILTER(#REF!, tblPiNAnalysis[Population Group]=B$5), 0, MATCH(_xlfn.CONCAT($Q$2, "%"), #REF!, 0))=$A7, 1, 0))=0, "",SUM(IF(INDEX(_xlfn._xlws.FILTER(#REF!, tblPiNAnalysis[Population Group]=B$5), 0, MATCH(_xlfn.CONCAT($Q$2, "%"), #REF!, 0))=$A7, 1, 0))))} | C7: {=IFERROR(IF(OR($A7="", C$5=""), "", IF(SUM(IF(INDEX(_xlfn._xlws.FILTER(#REF!, tblPiNAnalysis[Population Group]=C$5), 0, MATCH(_xlfn.CONCAT($Q$2, "%"), #REF!, 0))=$A7, 1, 0))=0, "",SUM(IF(INDEX(_xlfn._xlws.FILTER(#REF!, tblPiNAnalysis[Population Group]=C$5), 0, MATCH(_xlfn.CONCAT($Q$2, "%"), #REF!, 0))=$A7, 1, 0)))), "")} | D7: {=IFERROR(IF(OR($A7="", D$5=""), "", IF(SUM(IF(INDEX(_xlfn._xlws.FILTER(#REF!, tblPiNAnalysis[Population Group]=D$5), 0, MATCH(_xlfn.CONCAT($Q$2, "%"), #REF!, 0))=$A7, 1, 0))=0, "",SUM(IF(INDEX(_xlfn._xlws.FILTER(#REF!, tblPiNAnalysis[Population Group]=D$5), 0, MATCH(_xlfn.CONCAT($Q$2, "%"), #REF!, 0))=$A7, 1, 0)))), "")} | E7: {=IFERROR(IF(OR($A7="", E$5=""), "", IF(SUM(IF(INDEX(_xlfn._xlws.FILTER(#REF!, tblPiNAnalysis[Population Group]=E$5), 0, MATCH(_xlfn.CONCAT($Q$2, "%"), #REF!, 0))=$A7, 1, 0))=0, "",SUM(IF(INDEX(_xlfn._xlws.FILTER(#REF!, tblPiNAnalysis[Population Group]=E$5), 0, MATCH(_xlfn.CONCAT($Q$2, "%"), #REF!, 0))=$A7, 1, 0)))), "")} | F7: {=IFERROR(IF(OR($A7="", F$5=""), "", IF(SUM(IF(INDEX(_xlfn._xlws.FILTER(#REF!, tblPiNAnalysis[CCCM]=F$5), 0, MATCH(_xlfn.CONCAT($Q$2, "%"), #REF!, 0))=$A7, 1, 0))=0, "",SUM(IF(INDEX(_xlfn._xlws.FILTER(#REF!, tblPiNAnalysis[CCCM]=F$5), 0, MATCH(_xlfn.CONCAT($Q$2, "%"), #REF!, 0))=$A7, 1, 0)))), "")} | I7: {=IF($H7="", "", IF($H7=2, SUM(IF(INDEX(_xlfn._xlws.FILTER(#REF!,#REF!= I$5), 0, MATCH($Q$2,#REF!, 0))>1.9, 1, 0)), IF(SUM(IF(INDEX(_xlfn._xlws.FILTER(#REF!,#REF!= I$5), 0, MATCH($Q$2,#REF!, 0))=$H7, 1, 0))=0, "", SUM(IF(INDEX(_xlfn._xlws.FILTER(#REF!,#REF!= I$5), 0, MATCH($Q$2,#REF!, 0))=$H7, 1, 0)))))} | J7: {=IFERROR(IF(OR($H7="", J6=""), "", IF($H7=2, SUM(IF(INDEX(_xlfn._xlws.FILTER(#REF!,#REF!= J$5), 0, MATCH($Q$2,#REF!, 0))>1.9, 1, 0)), IF(SUM(IF(INDEX(_xlfn._xlws.FILTER(#REF!,#REF!= J$5), 0, MATCH($Q$2,#REF!, 0))=$H7, 1, 0))=0, "", SUM(IF(INDEX(_xlfn._xlws.FILTER(#REF!,#REF!= J$5), 0, MATCH($Q$2,#REF!, 0))=$H7, 1, 0))))), "")} | K7: {=IFERROR(IF(OR($H7="", K6=""), "", IF($H7=2, SUM(IF(INDEX(_xlfn._xlws.FILTER(#REF!,#REF!= K$5), 0, MATCH($Q$2,#REF!, 0))>1.9, 1, 0)), IF(SUM(IF(INDEX(_xlfn._xlws.FILTER(#REF!,#REF!= K$5), 0, MATCH($Q$2,#REF!, 0))=$H7, 1, 0))=0, "", SUM(IF(INDEX(_xlfn._xlws.FILTER(#REF!,#REF!= K$5), 0, MATCH($Q$2,#REF!, 0))=$H7, 1, 0))))), "")} | L7: {=IFERROR(IF(OR($H7="", L6=""), "", IF($H7=2, SUM(IF(INDEX(_xlfn._xlws.FILTER(#REF!,#REF!= L$5), 0, MATCH($Q$2,#REF!, 0))>1.9, 1, 0)), IF(SUM(IF(INDEX(_xlfn._xlws.FILTER(#REF!,#REF!= L$5), 0, MATCH($Q$2,#REF!, 0))=$H7, 1, 0))=0, "", SUM(IF(INDEX(_xlfn._xlws.FILTER(#REF!,#REF!= L$5), 0, MATCH($Q$2,#REF!, 0))=$H7, 1, 0))))), "")} | M7: {=IFERROR(IF(OR($H7="", M6=""), "", IF($H7=2, SUM(IF(INDEX(_xlfn._xlws.FILTER(#REF!,#REF!= M$5), 0, MATCH($Q$2,#REF!, 0))>1.9, 1, 0)), IF(SUM(IF(INDEX(_xlfn._xlws.FILTER(#REF!,#REF!= M$5), 0, MATCH($Q$2,#REF!, 0))=$H7, 1, 0))=0, "", SUM(IF(INDEX(_xlfn._xlws.FILTER(#REF!,#REF!= M$5), 0, MATCH($Q$2,#REF!, 0))=$H7, 1, 0))))), "")}
B8: {=IF($A8="", "", IF(SUM(IF(INDEX(_xlfn._xlws.FILTER(#REF!, tblPiNAnalysis[Population Group]=B$5), 0, MATCH(_xlfn.CONCAT($Q$2, "%"), #REF!, 0))=$A8, 1, 0))=0, "",SUM(IF(INDEX(_xlfn._xlws.FILTER(#REF!, tblPiNAnalysis[Population Group]=B$5), 0, MATCH(_xlfn.CONCAT($Q$2, "%"), #REF!, 0))=$A8, 1, 0))))} | C8: {=IFERROR(IF(OR($A8="", C$5=""), "", IF(SUM(IF(INDEX(_xlfn._xlws.FILTER(#REF!, tblPiNAnalysis[Population Group]=C$5), 0, MATCH(_xlfn.CONCAT($Q$2, "%"), #REF!, 0))=$A8, 1, 0))=0, "",SUM(IF(INDEX(_xlfn._xlws.FILTER(#REF!, tblPiNAnalysis[Population Group]=C$5), 0, MATCH(_xlfn.CONCAT($Q$2, "%"), #REF!, 0))=$A8, 1, 0)))), "")} | D8: {=IFERROR(IF(OR($A8="", D$5=""), "", IF(SUM(IF(INDEX(_xlfn._xlws.FILTER(#REF!, tblPiNAnalysis[Population Group]=D$5), 0, MATCH(_xlfn.CONCAT($Q$2, "%"), #REF!, 0))=$A8, 1, 0))=0, "",SUM(IF(INDEX(_xlfn._xlws.FILTER(#REF!, tblPiNAnalysis[Population Group]=D$5), 0, MATCH(_xlfn.CONCAT($Q$2, "%"), #REF!, 0))=$A8, 1, 0)))), "")} | E8: {=IFERROR(IF(OR($A8="", E$5=""), "", IF(SUM(IF(INDEX(_xlfn._xlws.FILTER(#REF!, tblPiNAnalysis[Population Group]=E$5), 0, MATCH(_xlfn.CONCAT($Q$2, "%"), #REF!, 0))=$A8, 1, 0))=0, "",SUM(IF(INDEX(_xlfn._xlws.FILTER(#REF!, tblPiNAnalysis[Population Group]=E$5), 0, MATCH(_xlfn.CONCAT($Q$2, "%"), #REF!, 0))=$A8, 1, 0)))), "")} | F8: {=IFERROR(IF(OR($A8="", F$5=""), "", IF(SUM(IF(INDEX(_xlfn._xlws.FILTER(#REF!, tblPiNAnalysis[CCCM]=F$5), 0, MATCH(_xlfn.CONCAT($Q$2, "%"), #REF!, 0))=$A8, 1, 0))=0, "",SUM(IF(INDEX(_xlfn._xlws.FILTER(#REF!, tblPiNAnalysis[CCCM]=F$5), 0, MATCH(_xlfn.CONCAT($Q$2, "%"), #REF!, 0))=$A8, 1, 0)))), "")} | I8: {=IF($H8="", "", IF($H8=2, SUM(IF(INDEX(_xlfn._xlws.FILTER(#REF!,#REF!= I$5), 0, MATCH($Q$2,#REF!, 0))>1.9, 1, 0)), IF(SUM(IF(INDEX(_xlfn._xlws.FILTER(#REF!,#REF!= I$5), 0, MATCH($Q$2,#REF!, 0))=$H8, 1, 0))=0, "", SUM(IF(INDEX(_xlfn._xlws.FILTER(#REF!,#REF!= I$5), 0, MATCH($Q$2,#REF!, 0))=$H8, 1, 0)))))} | J8: {=IFERROR(IF(OR($H8="", J7=""), "", IF($H8=2, SUM(IF(INDEX(_xlfn._xlws.FILTER(#REF!,#REF!= J$5), 0, MATCH($Q$2,#REF!, 0))>1.9, 1, 0)), IF(SUM(IF(INDEX(_xlfn._xlws.FILTER(#REF!,#REF!= J$5), 0, MATCH($Q$2,#REF!, 0))=$H8, 1, 0))=0, "", SUM(IF(INDEX(_xlfn._xlws.FILTER(#REF!,#REF!= J$5), 0, MATCH($Q$2,#REF!, 0))=$H8, 1, 0))))), "")} | K8: {=IFERROR(IF(OR($H8="", K7=""), "", IF($H8=2, SUM(IF(INDEX(_xlfn._xlws.FILTER(#REF!,#REF!= K$5), 0, MATCH($Q$2,#REF!, 0))>1.9, 1, 0)), IF(SUM(IF(INDEX(_xlfn._xlws.FILTER(#REF!,#REF!= K$5), 0, MATCH($Q$2,#REF!, 0))=$H8, 1, 0))=0, "", SUM(IF(INDEX(_xlfn._xlws.FILTER(#REF!,#REF!= K$5), 0, MATCH($Q$2,#REF!, 0))=$H8, 1, 0))))), "")} | L8: {=IFERROR(IF(OR($H8="", L7=""), "", IF($H8=2, SUM(IF(INDEX(_xlfn._xlws.FILTER(#REF!,#REF!= L$5), 0, MATCH($Q$2,#REF!, 0))>1.9, 1, 0)), IF(SUM(IF(INDEX(_xlfn._xlws.FILTER(#REF!,#REF!= L$5), 0, MATCH($Q$2,#REF!, 0))=$H8, 1, 0))=0, "", SUM(IF(INDEX(_xlfn._xlws.FILTER(#REF!,#REF!= L$5), 0, MATCH($Q$2,#REF!, 0))=$H8, 1, 0))))), "")} | M8: {=IFERROR(IF(OR($H8="", M7=""), "", IF($H8=2, SUM(IF(INDEX(_xlfn._xlws.FILTER(#REF!,#REF!= M$5), 0, MATCH($Q$2,#REF!, 0))>1.9, 1, 0)), IF(SUM(IF(INDEX(_xlfn._xlws.FILTER(#REF!,#REF!= M$5), 0, MATCH($Q$2,#REF!, 0))=$H8, 1, 0))=0, "", SUM(IF(INDEX(_xlfn._xlws.FILTER(#REF!,#REF!= M$5), 0, MATCH($Q$2,#REF!, 0))=$H8, 1, 0))))), "")}
B9: {=IF($A9="", "", IF(SUM(IF(INDEX(_xlfn._xlws.FILTER(#REF!, tblPiNAnalysis[Population Group]=B$5), 0, MATCH(_xlfn.CONCAT($Q$2, "%"), #REF!, 0))=$A9, 1, 0))=0, "",SUM(IF(INDEX(_xlfn._xlws.FILTER(#REF!, tblPiNAnalysis[Population Group]=B$5), 0, MATCH(_xlfn.CONCAT($Q$2, "%"), #REF!, 0))=$A9, 1, 0))))} | C9: {=IFERROR(IF(OR($A9="", C$5=""), "", IF(SUM(IF(INDEX(_xlfn._xlws.FILTER(#REF!, tblPiNAnalysis[Population Group]=C$5), 0, MATCH(_xlfn.CONCAT($Q$2, "%"), #REF!, 0))=$A9, 1, 0))=0, "",SUM(IF(INDEX(_xlfn._xlws.FILTER(#REF!, tblPiNAnalysis[Population Group]=C$5), 0, MATCH(_xlfn.CONCAT($Q$2, "%"), #REF!, 0))=$A9, 1, 0)))), "")} | D9: {=IFERROR(IF(OR($A9="", D$5=""), "", IF(SUM(IF(INDEX(_xlfn._xlws.FILTER(#REF!, tblPiNAnalysis[Population Group]=D$5), 0, MATCH(_xlfn.CONCAT($Q$2, "%"), #REF!, 0))=$A9, 1, 0))=0, "",SUM(IF(INDEX(_xlfn._xlws.FILTER(#REF!, tblPiNAnalysis[Population Group]=D$5), 0, MATCH(_xlfn.CONCAT($Q$2, "%"), #REF!, 0))=$A9, 1, 0)))), "")} | E9: {=IFERROR(IF(OR($A9="", E$5=""), "", IF(SUM(IF(INDEX(_xlfn._xlws.FILTER(#REF!, tblPiNAnalysis[Population Group]=E$5), 0, MATCH(_xlfn.CONCAT($Q$2, "%"), #REF!, 0))=$A9, 1, 0))=0, "",SUM(IF(INDEX(_xlfn._xlws.FILTER(#REF!, tblPiNAnalysis[Population Group]=E$5), 0, MATCH(_xlfn.CONCAT($Q$2, "%"), #REF!, 0))=$A9, 1, 0)))), "")} | F9: {=IFERROR(IF(OR($A9="", F$5=""), "", IF(SUM(IF(INDEX(_xlfn._xlws.FILTER(#REF!, tblPiNAnalysis[CCCM]=F$5), 0, MATCH(_xlfn.CONCAT($Q$2, "%"), #REF!, 0))=$A9, 1, 0))=0, "",SUM(IF(INDEX(_xlfn._xlws.FILTER(#REF!, tblPiNAnalysis[CCCM]=F$5), 0, MATCH(_xlfn.CONCAT($Q$2, "%"), #REF!, 0))=$A9, 1, 0)))), "")} | I9: {=IF($H9="", "", IF($H9=2, SUM(IF(INDEX(_xlfn._xlws.FILTER(#REF!,#REF!= I$5), 0, MATCH($Q$2,#REF!, 0))>1.9, 1, 0)), IF(SUM(IF(INDEX(_xlfn._xlws.FILTER(#REF!,#REF!= I$5), 0, MATCH($Q$2,#REF!, 0))=$H9, 1, 0))=0, "", SUM(IF(INDEX(_xlfn._xlws.FILTER(#REF!,#REF!= I$5), 0, MATCH($Q$2,#REF!, 0))=$H9, 1, 0)))))} | J9: {=IFERROR(IF(OR($H9="", J8=""), "", IF($H9=2, SUM(IF(INDEX(_xlfn._xlws.FILTER(#REF!,#REF!= J$5), 0, MATCH($Q$2,#REF!, 0))>1.9, 1, 0)), IF(SUM(IF(INDEX(_xlfn._xlws.FILTER(#REF!,#REF!= J$5), 0, MATCH($Q$2,#REF!, 0))=$H9, 1, 0))=0, "", SUM(IF(INDEX(_xlfn._xlws.FILTER(#REF!,#REF!= J$5), 0, MATCH($Q$2,#REF!, 0))=$H9, 1, 0))))), "")} | K9: {=IFERROR(IF(OR($H9="", K8=""), "", IF($H9=2, SUM(IF(INDEX(_xlfn._xlws.FILTER(#REF!,#REF!= K$5), 0, MATCH($Q$2,#REF!, 0))>1.9, 1, 0)), IF(SUM(IF(INDEX(_xlfn._xlws.FILTER(#REF!,#REF!= K$5), 0, MATCH($Q$2,#REF!, 0))=$H9, 1, 0))=0, "", SUM(IF(INDEX(_xlfn._xlws.FILTER(#REF!,#REF!= K$5), 0, MATCH($Q$2,#REF!, 0))=$H9, 1, 0))))), "")} | L9: {=IFERROR(IF(OR($H9="", L8=""), "", IF($H9=2, SUM(IF(INDEX(_xlfn._xlws.FILTER(#REF!,#REF!= L$5), 0, MATCH($Q$2,#REF!, 0))>1.9, 1, 0)), IF(SUM(IF(INDEX(_xlfn._xlws.FILTER(#REF!,#REF!= L$5), 0, MATCH($Q$2,#REF!, 0))=$H9, 1, 0))=0, "", SUM(IF(INDEX(_xlfn._xlws.FILTER(#REF!,#REF!= L$5), 0, MATCH($Q$2,#REF!, 0))=$H9, 1, 0))))), "")} | M9: {=IFERROR(IF(OR($H9="", M8=""), "", IF($H9=2, SUM(IF(INDEX(_xlfn._xlws.FILTER(#REF!,#REF!= M$5), 0, MATCH($Q$2,#REF!, 0))>1.9, 1, 0)), IF(SUM(IF(INDEX(_xlfn._xlws.FILTER(#REF!,#REF!= M$5), 0, MATCH($Q$2,#REF!, 0))=$H9, 1, 0))=0, "", SUM(IF(INDEX(_xlfn._xlws.FILTER(#REF!,#REF!= M$5), 0, MATCH($Q$2,#REF!, 0))=$H9, 1, 0))))), "")}
B10: {=IF($A10="", "", IF(SUM(IF(INDEX(_xlfn._xlws.FILTER(#REF!, tblPiNAnalysis[Population Group]=B$5), 0, MATCH(_xlfn.CONCAT($Q$2, "%"), #REF!, 0))=$A10, 1, 0))=0, "",SUM(IF(INDEX(_xlfn._xlws.FILTER(#REF!, tblPiNAnalysis[Population Group]=B$5), 0, MATCH(_xlfn.CONCAT($Q$2, "%"), #REF!, 0))=$A10, 1, 0))))} | C10: {=IFERROR(IF(OR($A10="", C$5=""), "", IF(SUM(IF(INDEX(_xlfn._xlws.FILTER(#REF!, tblPiNAnalysis[Population Group]=C$5), 0, MATCH(_xlfn.CONCAT($Q$2, "%"), #REF!, 0))=$A10, 1, 0))=0, "",SUM(IF(INDEX(_xlfn._xlws.FILTER(#REF!, tblPiNAnalysis[Population Group]=C$5), 0, MATCH(_xlfn.CONCAT($Q$2, "%"), #REF!, 0))=$A10, 1, 0)))), "")} | D10: {=IFERROR(IF(OR($A10="", D$5=""), "", IF(SUM(IF(INDEX(_xlfn._xlws.FILTER(#REF!, tblPiNAnalysis[Population Group]=D$5), 0, MATCH(_xlfn.CONCAT($Q$2, "%"), #REF!, 0))=$A10, 1, 0))=0, "",SUM(IF(INDEX(_xlfn._xlws.FILTER(#REF!, tblPiNAnalysis[Population Group]=D$5), 0, MATCH(_xlfn.CONCAT($Q$2, "%"), #REF!, 0))=$A10, 1, 0)))), "")} | E10: {=IFERROR(IF(OR($A10="", E$5=""), "", IF(SUM(IF(INDEX(_xlfn._xlws.FILTER(#REF!, tblPiNAnalysis[Population Group]=E$5), 0, MATCH(_xlfn.CONCAT($Q$2, "%"), #REF!, 0))=$A10, 1, 0))=0, "",SUM(IF(INDEX(_xlfn._xlws.FILTER(#REF!, tblPiNAnalysis[Population Group]=E$5), 0, MATCH(_xlfn.CONCAT($Q$2, "%"), #REF!, 0))=$A10, 1, 0)))), "")} | F10: {=IFERROR(IF(OR($A10="", F$5=""), "", IF(SUM(IF(INDEX(_xlfn._xlws.FILTER(#REF!, tblPiNAnalysis[CCCM]=F$5), 0, MATCH(_xlfn.CONCAT($Q$2, "%"), #REF!, 0))=$A10, 1, 0))=0, "",SUM(IF(INDEX(_xlfn._xlws.FILTER(#REF!, tblPiNAnalysis[CCCM]=F$5), 0, MATCH(_xlfn.CONCAT($Q$2, "%"), #REF!, 0))=$A10, 1, 0)))), "")} | I10: {=IF($H10="", "", IF($H10=2, SUM(IF(INDEX(_xlfn._xlws.FILTER(#REF!,#REF!= I$5), 0, MATCH($Q$2,#REF!, 0))>1.9, 1, 0)), IF(SUM(IF(INDEX(_xlfn._xlws.FILTER(#REF!,#REF!= I$5), 0, MATCH($Q$2,#REF!, 0))=$H10, 1, 0))=0, "", SUM(IF(INDEX(_xlfn._xlws.FILTER(#REF!,#REF!= I$5), 0, MATCH($Q$2,#REF!, 0))=$H10, 1, 0)))))} | J10: {=IFERROR(IF(OR($H10="", J9=""), "", IF($H10=2, SUM(IF(INDEX(_xlfn._xlws.FILTER(#REF!,#REF!= J$5), 0, MATCH($Q$2,#REF!, 0))>1.9, 1, 0)), IF(SUM(IF(INDEX(_xlfn._xlws.FILTER(#REF!,#REF!= J$5), 0, MATCH($Q$2,#REF!, 0))=$H10, 1, 0))=0, "", SUM(IF(INDEX(_xlfn._xlws.FILTER(#REF!,#REF!= J$5), 0, MATCH($Q$2,#REF!, 0))=$H10, 1, 0))))), "")} | K10: {=IFERROR(IF(OR($H10="", K9=""), "", IF($H10=2, SUM(IF(INDEX(_xlfn._xlws.FILTER(#REF!,#REF!= K$5), 0, MATCH($Q$2,#REF!, 0))>1.9, 1, 0)), IF(SUM(IF(INDEX(_xlfn._xlws.FILTER(#REF!,#REF!= K$5), 0, MATCH($Q$2,#REF!, 0))=$H10, 1, 0))=0, "", SUM(IF(INDEX(_xlfn._xlws.FILTER(#REF!,#REF!= K$5), 0, MATCH($Q$2,#REF!, 0))=$H10, 1, 0))))), "")} | L10: {=IFERROR(IF(OR($H10="", L9=""), "", IF($H10=2, SUM(IF(INDEX(_xlfn._xlws.FILTER(#REF!,#REF!= L$5), 0, MATCH($Q$2,#REF!, 0))>1.9, 1, 0)), IF(SUM(IF(INDEX(_xlfn._xlws.FILTER(#REF!,#REF!= L$5), 0, MATCH($Q$2,#REF!, 0))=$H10, 1, 0))=0, "", SUM(IF(INDEX(_xlfn._xlws.FILTER(#REF!,#REF!= L$5), 0, MATCH($Q$2,#REF!, 0))=$H10, 1, 0))))), "")} | M10: {=IFERROR(IF(OR($H10="", M9=""), "", IF($H10=2, SUM(IF(INDEX(_xlfn._xlws.FILTER(#REF!,#REF!= M$5), 0, MATCH($Q$2,#REF!, 0))>1.9, 1, 0)), IF(SUM(IF(INDEX(_xlfn._xlws.FILTER(#REF!,#REF!= M$5), 0, MATCH($Q$2,#REF!, 0))=$H10, 1, 0))=0, "", SUM(IF(INDEX(_xlfn._xlws.FILTER(#REF!,#REF!= M$5), 0, MATCH($Q$2,#REF!, 0))=$H10, 1, 0))))), "")}
B11: {=IF($A11="", "", IF(SUM(IF(INDEX(_xlfn._xlws.FILTER(#REF!, tblPiNAnalysis[Population Group]=B$5), 0, MATCH(_xlfn.CONCAT($Q$2, "%"), #REF!, 0))=$A11, 1, 0))=0, "",SUM(IF(INDEX(_xlfn._xlws.FILTER(#REF!, tblPiNAnalysis[Population Group]=B$5), 0, MATCH(_xlfn.CONCAT($Q$2, "%"), #REF!, 0))=$A11, 1, 0))))} | C11: {=IFERROR(IF(OR($A11="", C$5=""), "", IF(SUM(IF(INDEX(_xlfn._xlws.FILTER(#REF!, tblPiNAnalysis[Population Group]=C$5), 0, MATCH(_xlfn.CONCAT($Q$2, "%"), #REF!, 0))=$A11, 1, 0))=0, "",SUM(IF(INDEX(_xlfn._xlws.FILTER(#REF!, tblPiNAnalysis[Population Group]=C$5), 0, MATCH(_xlfn.CONCAT($Q$2, "%"), #REF!, 0))=$A11, 1, 0)))), "")} | D11: {=IFERROR(IF(OR($A11="", D$5=""), "", IF(SUM(IF(INDEX(_xlfn._xlws.FILTER(#REF!, tblPiNAnalysis[Population Group]=D$5), 0, MATCH(_xlfn.CONCAT($Q$2, "%"), #REF!, 0))=$A11, 1, 0))=0, "",SUM(IF(INDEX(_xlfn._xlws.FILTER(#REF!, tblPiNAnalysis[Population Group]=D$5), 0, MATCH(_xlfn.CONCAT($Q$2, "%"), #REF!, 0))=$A11, 1, 0)))), "")} | E11: {=IFERROR(IF(OR($A11="", E$5=""), "", IF(SUM(IF(INDEX(_xlfn._xlws.FILTER(#REF!, tblPiNAnalysis[Population Group]=E$5), 0, MATCH(_xlfn.CONCAT($Q$2, "%"), #REF!, 0))=$A11, 1, 0))=0, "",SUM(IF(INDEX(_xlfn._xlws.FILTER(#REF!, tblPiNAnalysis[Population Group]=E$5), 0, MATCH(_xlfn.CONCAT($Q$2, "%"), #REF!, 0))=$A11, 1, 0)))), "")} | F11: {=IFERROR(IF(OR($A11="", F$5=""), "", IF(SUM(IF(INDEX(_xlfn._xlws.FILTER(#REF!, tblPiNAnalysis[CCCM]=F$5), 0, MATCH(_xlfn.CONCAT($Q$2, "%"), #REF!, 0))=$A11, 1, 0))=0, "",SUM(IF(INDEX(_xlfn._xlws.FILTER(#REF!, tblPiNAnalysis[CCCM]=F$5), 0, MATCH(_xlfn.CONCAT($Q$2, "%"), #REF!, 0))=$A11, 1, 0)))), "")} | I11: {=IF($H11="", "", IF($H11=2, SUM(IF(INDEX(_xlfn._xlws.FILTER(#REF!,#REF!= I$5), 0, MATCH($Q$2,#REF!, 0))>1.9, 1, 0)), IF(SUM(IF(INDEX(_xlfn._xlws.FILTER(#REF!,#REF!= I$5), 0, MATCH($Q$2,#REF!, 0))=$H11, 1, 0))=0, "", SUM(IF(INDEX(_xlfn._xlws.FILTER(#REF!,#REF!= I$5), 0, MATCH($Q$2,#REF!, 0))=$H11, 1, 0)))))} | J11: {=IFERROR(IF(OR($H11="", J10=""), "", IF($H11=2, SUM(IF(INDEX(_xlfn._xlws.FILTER(#REF!,#REF!= J$5), 0, MATCH($Q$2,#REF!, 0))>1.9, 1, 0)), IF(SUM(IF(INDEX(_xlfn._xlws.FILTER(#REF!,#REF!= J$5), 0, MATCH($Q$2,#REF!, 0))=$H11, 1, 0))=0, "", SUM(IF(INDEX(_xlfn._xlws.FILTER(#REF!,#REF!= J$5), 0, MATCH($Q$2,#REF!, 0))=$H11, 1, 0))))), "")} | K11: {=IFERROR(IF(OR($H11="", K10=""), "", IF($H11=2, SUM(IF(INDEX(_xlfn._xlws.FILTER(#REF!,#REF!= K$5), 0, MATCH($Q$2,#REF!, 0))>1.9, 1, 0)), IF(SUM(IF(INDEX(_xlfn._xlws.FILTER(#REF!,#REF!= K$5), 0, MATCH($Q$2,#REF!, 0))=$H11, 1, 0))=0, "", SUM(IF(INDEX(_xlfn._xlws.FILTER(#REF!,#REF!= K$5), 0, MATCH($Q$2,#REF!, 0))=$H11, 1, 0))))), "")} | L11: {=IFERROR(IF(OR($H11="", L10=""), "", IF($H11=2, SUM(IF(INDEX(_xlfn._xlws.FILTER(#REF!,#REF!= L$5), 0, MATCH($Q$2,#REF!, 0))>1.9, 1, 0)), IF(SUM(IF(INDEX(_xlfn._xlws.FILTER(#REF!,#REF!= L$5), 0, MATCH($Q$2,#REF!, 0))=$H11, 1, 0))=0, "", SUM(IF(INDEX(_xlfn._xlws.FILTER(#REF!,#REF!= L$5), 0, MATCH($Q$2,#REF!, 0))=$H11, 1, 0))))), "")} | M11: {=IFERROR(IF(OR($H11="", M10=""), "", IF($H11=2, SUM(IF(INDEX(_xlfn._xlws.FILTER(#REF!,#REF!= M$5), 0, MATCH($Q$2,#REF!, 0))>1.9, 1, 0)), IF(SUM(IF(INDEX(_xlfn._xlws.FILTER(#REF!,#REF!= M$5), 0, MATCH($Q$2,#REF!, 0))=$H11, 1, 0))=0, "", SUM(IF(INDEX(_xlfn._xlws.FILTER(#REF!,#REF!= M$5), 0, MATCH($Q$2,#REF!, 0))=$H11, 1, 0))))), "")}
B12: {=IF($A12="", "", IF(SUM(IF(INDEX(_xlfn._xlws.FILTER(#REF!, tblPiNAnalysis[Population Group]=B$5), 0, MATCH(_xlfn.CONCAT($Q$2, "%"), #REF!, 0))=$A12, 1, 0))=0, "",SUM(IF(INDEX(_xlfn._xlws.FILTER(#REF!, tblPiNAnalysis[Population Group]=B$5), 0, MATCH(_xlfn.CONCAT($Q$2, "%"), #REF!, 0))=$A12, 1, 0))))} | C12: {=IFERROR(IF(OR($A12="", C$5=""), "", IF(SUM(IF(INDEX(_xlfn._xlws.FILTER(#REF!, tblPiNAnalysis[Population Group]=C$5), 0, MATCH(_xlfn.CONCAT($Q$2, "%"), #REF!, 0))=$A12, 1, 0))=0, "",SUM(IF(INDEX(_xlfn._xlws.FILTER(#REF!, tblPiNAnalysis[Population Group]=C$5), 0, MATCH(_xlfn.CONCAT($Q$2, "%"), #REF!, 0))=$A12, 1, 0)))), "")} | D12: {=IFERROR(IF(OR($A12="", D$5=""), "", IF(SUM(IF(INDEX(_xlfn._xlws.FILTER(#REF!, tblPiNAnalysis[Population Group]=D$5), 0, MATCH(_xlfn.CONCAT($Q$2, "%"), #REF!, 0))=$A12, 1, 0))=0, "",SUM(IF(INDEX(_xlfn._xlws.FILTER(#REF!, tblPiNAnalysis[Population Group]=D$5), 0, MATCH(_xlfn.CONCAT($Q$2, "%"), #REF!, 0))=$A12, 1, 0)))), "")} | E12: {=IFERROR(IF(OR($A12="", E$5=""), "", IF(SUM(IF(INDEX(_xlfn._xlws.FILTER(#REF!, tblPiNAnalysis[Population Group]=E$5), 0, MATCH(_xlfn.CONCAT($Q$2, "%"), #REF!, 0))=$A12, 1, 0))=0, "",SUM(IF(INDEX(_xlfn._xlws.FILTER(#REF!, tblPiNAnalysis[Population Group]=E$5), 0, MATCH(_xlfn.CONCAT($Q$2, "%"), #REF!, 0))=$A12, 1, 0)))), "")} | F12: {=IFERROR(IF(OR($A12="", F$5=""), "", IF(SUM(IF(INDEX(_xlfn._xlws.FILTER(#REF!, tblPiNAnalysis[CCCM]=F$5), 0, MATCH(_xlfn.CONCAT($Q$2, "%"), #REF!, 0))=$A12, 1, 0))=0, "",SUM(IF(INDEX(_xlfn._xlws.FILTER(#REF!, tblPiNAnalysis[CCCM]=F$5), 0, MATCH(_xlfn.CONCAT($Q$2, "%"), #REF!, 0))=$A12, 1, 0)))), "")} | I12: {=IF($H12="", "", IF($H12=2, SUM(IF(INDEX(_xlfn._xlws.FILTER(#REF!,#REF!= I$5), 0, MATCH($Q$2,#REF!, 0))>1.9, 1, 0)), IF(SUM(IF(INDEX(_xlfn._xlws.FILTER(#REF!,#REF!= I$5), 0, MATCH($Q$2,#REF!, 0))=$H12, 1, 0))=0, "", SUM(IF(INDEX(_xlfn._xlws.FILTER(#REF!,#REF!= I$5), 0, MATCH($Q$2,#REF!, 0))=$H12, 1, 0)))))} | J12: {=IFERROR(IF(OR($H12="", J11=""), "", IF($H12=2, SUM(IF(INDEX(_xlfn._xlws.FILTER(#REF!,#REF!= J$5), 0, MATCH($Q$2,#REF!, 0))>1.9, 1, 0)), IF(SUM(IF(INDEX(_xlfn._xlws.FILTER(#REF!,#REF!= J$5), 0, MATCH($Q$2,#REF!, 0))=$H12, 1, 0))=0, "", SUM(IF(INDEX(_xlfn._xlws.FILTER(#REF!,#REF!= J$5), 0, MATCH($Q$2,#REF!, 0))=$H12, 1, 0))))), "")} | K12: {=IFERROR(IF(OR($H12="", K11=""), "", IF($H12=2, SUM(IF(INDEX(_xlfn._xlws.FILTER(#REF!,#REF!= K$5), 0, MATCH($Q$2,#REF!, 0))>1.9, 1, 0)), IF(SUM(IF(INDEX(_xlfn._xlws.FILTER(#REF!,#REF!= K$5), 0, MATCH($Q$2,#REF!, 0))=$H12, 1, 0))=0, "", SUM(IF(INDEX(_xlfn._xlws.FILTER(#REF!,#REF!= K$5), 0, MATCH($Q$2,#REF!, 0))=$H12, 1, 0))))), "")} | L12: {=IFERROR(IF(OR($H12="", L11=""), "", IF($H12=2, SUM(IF(INDEX(_xlfn._xlws.FILTER(#REF!,#REF!= L$5), 0, MATCH($Q$2,#REF!, 0))>1.9, 1, 0)), IF(SUM(IF(INDEX(_xlfn._xlws.FILTER(#REF!,#REF!= L$5), 0, MATCH($Q$2,#REF!, 0))=$H12, 1, 0))=0, "", SUM(IF(INDEX(_xlfn._xlws.FILTER(#REF!,#REF!= L$5), 0, MATCH($Q$2,#REF!, 0))=$H12, 1, 0))))), "")} | M12: {=IFERROR(IF(OR($H12="", M11=""), "", IF($H12=2, SUM(IF(INDEX(_xlfn._xlws.FILTER(#REF!,#REF!= M$5), 0, MATCH($Q$2,#REF!, 0))>1.9, 1, 0)), IF(SUM(IF(INDEX(_xlfn._xlws.FILTER(#REF!,#REF!= M$5), 0, MATCH($Q$2,#REF!, 0))=$H12, 1, 0))=0, "", SUM(IF(INDEX(_xlfn._xlws.FILTER(#REF!,#REF!= M$5), 0, MATCH($Q$2,#REF!, 0))=$H12, 1, 0))))), "")}
B13: {=IF($A13="", "", IF(SUM(IF(INDEX(_xlfn._xlws.FILTER(#REF!, tblPiNAnalysis[Population Group]=B$5), 0, MATCH(_xlfn.CONCAT($Q$2, "%"), #REF!, 0))=$A13, 1, 0))=0, "",SUM(IF(INDEX(_xlfn._xlws.FILTER(#REF!, tblPiNAnalysis[Population Group]=B$5), 0, MATCH(_xlfn.CONCAT($Q$2, "%"), #REF!, 0))=$A13, 1, 0))))} | C13: {=IFERROR(IF(OR($A13="", C$5=""), "", IF(SUM(IF(INDEX(_xlfn._xlws.FILTER(#REF!, tblPiNAnalysis[Population Group]=C$5), 0, MATCH(_xlfn.CONCAT($Q$2, "%"), #REF!, 0))=$A13, 1, 0))=0, "",SUM(IF(INDEX(_xlfn._xlws.FILTER(#REF!, tblPiNAnalysis[Population Group]=C$5), 0, MATCH(_xlfn.CONCAT($Q$2, "%"), #REF!, 0))=$A13, 1, 0)))), "")} | D13: {=IFERROR(IF(OR($A13="", D$5=""), "", IF(SUM(IF(INDEX(_xlfn._xlws.FILTER(#REF!, tblPiNAnalysis[Population Group]=D$5), 0, MATCH(_xlfn.CONCAT($Q$2, "%"), #REF!, 0))=$A13, 1, 0))=0, "",SUM(IF(INDEX(_xlfn._xlws.FILTER(#REF!, tblPiNAnalysis[Population Group]=D$5), 0, MATCH(_xlfn.CONCAT($Q$2, "%"), #REF!, 0))=$A13, 1, 0)))), "")} | E13: {=IFERROR(IF(OR($A13="", E$5=""), "", IF(SUM(IF(INDEX(_xlfn._xlws.FILTER(#REF!, tblPiNAnalysis[Population Group]=E$5), 0, MATCH(_xlfn.CONCAT($Q$2, "%"), #REF!, 0))=$A13, 1, 0))=0, "",SUM(IF(INDEX(_xlfn._xlws.FILTER(#REF!, tblPiNAnalysis[Population Group]=E$5), 0, MATCH(_xlfn.CONCAT($Q$2, "%"), #REF!, 0))=$A13, 1, 0)))), "")} | F13: {=IFERROR(IF(OR($A13="", F$5=""), "", IF(SUM(IF(INDEX(_xlfn._xlws.FILTER(#REF!, tblPiNAnalysis[CCCM]=F$5), 0, MATCH(_xlfn.CONCAT($Q$2, "%"), #REF!, 0))=$A13, 1, 0))=0, "",SUM(IF(INDEX(_xlfn._xlws.FILTER(#REF!, tblPiNAnalysis[CCCM]=F$5), 0, MATCH(_xlfn.CONCAT($Q$2, "%"), #REF!, 0))=$A13, 1, 0)))), "")} | I13: {=IF($H13="", "", IF($H13=2, SUM(IF(INDEX(_xlfn._xlws.FILTER(#REF!,#REF!= I$5), 0, MATCH($Q$2,#REF!, 0))>1.9, 1, 0)), IF(SUM(IF(INDEX(_xlfn._xlws.FILTER(#REF!,#REF!= I$5), 0, MATCH($Q$2,#REF!, 0))=$H13, 1, 0))=0, "", SUM(IF(INDEX(_xlfn._xlws.FILTER(#REF!,#REF!= I$5), 0, MATCH($Q$2,#REF!, 0))=$H13, 1, 0)))))} | J13: {=IFERROR(IF(OR($H13="", J12=""), "", IF($H13=2, SUM(IF(INDEX(_xlfn._xlws.FILTER(#REF!,#REF!= J$5), 0, MATCH($Q$2,#REF!, 0))>1.9, 1, 0)), IF(SUM(IF(INDEX(_xlfn._xlws.FILTER(#REF!,#REF!= J$5), 0, MATCH($Q$2,#REF!, 0))=$H13, 1, 0))=0, "", SUM(IF(INDEX(_xlfn._xlws.FILTER(#REF!,#REF!= J$5), 0, MATCH($Q$2,#REF!, 0))=$H13, 1, 0))))), "")} | K13: {=IFERROR(IF(OR($H13="", K12=""), "", IF($H13=2, SUM(IF(INDEX(_xlfn._xlws.FILTER(#REF!,#REF!= K$5), 0, MATCH($Q$2,#REF!, 0))>1.9, 1, 0)), IF(SUM(IF(INDEX(_xlfn._xlws.FILTER(#REF!,#REF!= K$5), 0, MATCH($Q$2,#REF!, 0))=$H13, 1, 0))=0, "", SUM(IF(INDEX(_xlfn._xlws.FILTER(#REF!,#REF!= K$5), 0, MATCH($Q$2,#REF!, 0))=$H13, 1, 0))))), "")} | L13: {=IFERROR(IF(OR($H13="", L12=""), "", IF($H13=2, SUM(IF(INDEX(_xlfn._xlws.FILTER(#REF!,#REF!= L$5), 0, MATCH($Q$2,#REF!, 0))>1.9, 1, 0)), IF(SUM(IF(INDEX(_xlfn._xlws.FILTER(#REF!,#REF!= L$5), 0, MATCH($Q$2,#REF!, 0))=$H13, 1, 0))=0, "", SUM(IF(INDEX(_xlfn._xlws.FILTER(#REF!,#REF!= L$5), 0, MATCH($Q$2,#REF!, 0))=$H13, 1, 0))))), "")} | M13: {=IFERROR(IF(OR($H13="", M12=""), "", IF($H13=2, SUM(IF(INDEX(_xlfn._xlws.FILTER(#REF!,#REF!= M$5), 0, MATCH($Q$2,#REF!, 0))>1.9, 1, 0)), IF(SUM(IF(INDEX(_xlfn._xlws.FILTER(#REF!,#REF!= M$5), 0, MATCH($Q$2,#REF!, 0))=$H13, 1, 0))=0, "", SUM(IF(INDEX(_xlfn._xlws.FILTER(#REF!,#REF!= M$5), 0, MATCH($Q$2,#REF!, 0))=$H13, 1, 0))))), "")}
B14: {=IF($A14="", "", IF(SUM(IF(INDEX(_xlfn._xlws.FILTER(#REF!, tblPiNAnalysis[Population Group]=B$5), 0, MATCH(_xlfn.CONCAT($Q$2, "%"), #REF!, 0))=$A14, 1, 0))=0, "",SUM(IF(INDEX(_xlfn._xlws.FILTER(#REF!, tblPiNAnalysis[Population Group]=B$5), 0, MATCH(_xlfn.CONCAT($Q$2, "%"), #REF!, 0))=$A14, 1, 0))))} | C14: {=IFERROR(IF(OR($A14="", C$5=""), "", IF(SUM(IF(INDEX(_xlfn._xlws.FILTER(#REF!, tblPiNAnalysis[Population Group]=C$5), 0, MATCH(_xlfn.CONCAT($Q$2, "%"), #REF!, 0))=$A14, 1, 0))=0, "",SUM(IF(INDEX(_xlfn._xlws.FILTER(#REF!, tblPiNAnalysis[Population Group]=C$5), 0, MATCH(_xlfn.CONCAT($Q$2, "%"), #REF!, 0))=$A14, 1, 0)))), "")} | D14: {=IFERROR(IF(OR($A14="", D$5=""), "", IF(SUM(IF(INDEX(_xlfn._xlws.FILTER(#REF!, tblPiNAnalysis[Population Group]=D$5), 0, MATCH(_xlfn.CONCAT($Q$2, "%"), #REF!, 0))=$A14, 1, 0))=0, "",SUM(IF(INDEX(_xlfn._xlws.FILTER(#REF!, tblPiNAnalysis[Population Group]=D$5), 0, MATCH(_xlfn.CONCAT($Q$2, "%"), #REF!, 0))=$A14, 1, 0)))), "")} | E14: {=IFERROR(IF(OR($A14="", E$5=""), "", IF(SUM(IF(INDEX(_xlfn._xlws.FILTER(#REF!, tblPiNAnalysis[Population Group]=E$5), 0, MATCH(_xlfn.CONCAT($Q$2, "%"), #REF!, 0))=$A14, 1, 0))=0, "",SUM(IF(INDEX(_xlfn._xlws.FILTER(#REF!, tblPiNAnalysis[Population Group]=E$5), 0, MATCH(_xlfn.CONCAT($Q$2, "%"), #REF!, 0))=$A14, 1, 0)))), "")} | F14: {=IFERROR(IF(OR($A14="", F$5=""), "", IF(SUM(IF(INDEX(_xlfn._xlws.FILTER(#REF!, tblPiNAnalysis[CCCM]=F$5), 0, MATCH(_xlfn.CONCAT($Q$2, "%"), #REF!, 0))=$A14, 1, 0))=0, "",SUM(IF(INDEX(_xlfn._xlws.FILTER(#REF!, tblPiNAnalysis[CCCM]=F$5), 0, MATCH(_xlfn.CONCAT($Q$2, "%"), #REF!, 0))=$A14, 1, 0)))), "")} | I14: {=IF($H14="", "", IF($H14=2, SUM(IF(INDEX(_xlfn._xlws.FILTER(#REF!,#REF!= I$5), 0, MATCH($Q$2,#REF!, 0))>1.9, 1, 0)), IF(SUM(IF(INDEX(_xlfn._xlws.FILTER(#REF!,#REF!= I$5), 0, MATCH($Q$2,#REF!, 0))=$H14, 1, 0))=0, "", SUM(IF(INDEX(_xlfn._xlws.FILTER(#REF!,#REF!= I$5), 0, MATCH($Q$2,#REF!, 0))=$H14, 1, 0)))))} | J14: {=IFERROR(IF(OR($H14="", J13=""), "", IF($H14=2, SUM(IF(INDEX(_xlfn._xlws.FILTER(#REF!,#REF!= J$5), 0, MATCH($Q$2,#REF!, 0))>1.9, 1, 0)), IF(SUM(IF(INDEX(_xlfn._xlws.FILTER(#REF!,#REF!= J$5), 0, MATCH($Q$2,#REF!, 0))=$H14, 1, 0))=0, "", SUM(IF(INDEX(_xlfn._xlws.FILTER(#REF!,#REF!= J$5), 0, MATCH($Q$2,#REF!, 0))=$H14, 1, 0))))), "")} | K14: {=IFERROR(IF(OR($H14="", K13=""), "", IF($H14=2, SUM(IF(INDEX(_xlfn._xlws.FILTER(#REF!,#REF!= K$5), 0, MATCH($Q$2,#REF!, 0))>1.9, 1, 0)), IF(SUM(IF(INDEX(_xlfn._xlws.FILTER(#REF!,#REF!= K$5), 0, MATCH($Q$2,#REF!, 0))=$H14, 1, 0))=0, "", SUM(IF(INDEX(_xlfn._xlws.FILTER(#REF!,#REF!= K$5), 0, MATCH($Q$2,#REF!, 0))=$H14, 1, 0))))), "")} | L14: {=IFERROR(IF(OR($H14="", L13=""), "", IF($H14=2, SUM(IF(INDEX(_xlfn._xlws.FILTER(#REF!,#REF!= L$5), 0, MATCH($Q$2,#REF!, 0))>1.9, 1, 0)), IF(SUM(IF(INDEX(_xlfn._xlws.FILTER(#REF!,#REF!= L$5), 0, MATCH($Q$2,#REF!, 0))=$H14, 1, 0))=0, "", SUM(IF(INDEX(_xlfn._xlws.FILTER(#REF!,#REF!= L$5), 0, MATCH($Q$2,#REF!, 0))=$H14, 1, 0))))), "")} | M14: {=IFERROR(IF(OR($H14="", M13=""), "", IF($H14=2, SUM(IF(INDEX(_xlfn._xlws.FILTER(#REF!,#REF!= M$5), 0, MATCH($Q$2,#REF!, 0))>1.9, 1, 0)), IF(SUM(IF(INDEX(_xlfn._xlws.FILTER(#REF!,#REF!= M$5), 0, MATCH($Q$2,#REF!, 0))=$H14, 1, 0))=0, "", SUM(IF(INDEX(_xlfn._xlws.FILTER(#REF!,#REF!= M$5), 0, MATCH($Q$2,#REF!, 0))=$H14, 1, 0))))), "")}
B15: {=IF($A15="", "", IF(SUM(IF(INDEX(_xlfn._xlws.FILTER(#REF!, tblPiNAnalysis[Population Group]=B$5), 0, MATCH(_xlfn.CONCAT($Q$2, "%"), #REF!, 0))=$A15, 1, 0))=0, "",SUM(IF(INDEX(_xlfn._xlws.FILTER(#REF!, tblPiNAnalysis[Population Group]=B$5), 0, MATCH(_xlfn.CONCAT($Q$2, "%"), #REF!, 0))=$A15, 1, 0))))} | C15: {=IFERROR(IF(OR($A15="", C$5=""), "", IF(SUM(IF(INDEX(_xlfn._xlws.FILTER(#REF!, tblPiNAnalysis[Population Group]=C$5), 0, MATCH(_xlfn.CONCAT($Q$2, "%"), #REF!, 0))=$A15, 1, 0))=0, "",SUM(IF(INDEX(_xlfn._xlws.FILTER(#REF!, tblPiNAnalysis[Population Group]=C$5), 0, MATCH(_xlfn.CONCAT($Q$2, "%"), #REF!, 0))=$A15, 1, 0)))), "")} | D15: {=IFERROR(IF(OR($A15="", D$5=""), "", IF(SUM(IF(INDEX(_xlfn._xlws.FILTER(#REF!, tblPiNAnalysis[Population Group]=D$5), 0, MATCH(_xlfn.CONCAT($Q$2, "%"), #REF!, 0))=$A15, 1, 0))=0, "",SUM(IF(INDEX(_xlfn._xlws.FILTER(#REF!, tblPiNAnalysis[Population Group]=D$5), 0, MATCH(_xlfn.CONCAT($Q$2, "%"), #REF!, 0))=$A15, 1, 0)))), "")} | E15: {=IFERROR(IF(OR($A15="", E$5=""), "", IF(SUM(IF(INDEX(_xlfn._xlws.FILTER(#REF!, tblPiNAnalysis[Population Group]=E$5), 0, MATCH(_xlfn.CONCAT($Q$2, "%"), #REF!, 0))=$A15, 1, 0))=0, "",SUM(IF(INDEX(_xlfn._xlws.FILTER(#REF!, tblPiNAnalysis[Population Group]=E$5), 0, MATCH(_xlfn.CONCAT($Q$2, "%"), #REF!, 0))=$A15, 1, 0)))), "")} | F15: {=IFERROR(IF(OR($A15="", F$5=""), "", IF(SUM(IF(INDEX(_xlfn._xlws.FILTER(#REF!, tblPiNAnalysis[CCCM]=F$5), 0, MATCH(_xlfn.CONCAT($Q$2, "%"), #REF!, 0))=$A15, 1, 0))=0, "",SUM(IF(INDEX(_xlfn._xlws.FILTER(#REF!, tblPiNAnalysis[CCCM]=F$5), 0, MATCH(_xlfn.CONCAT($Q$2, "%"), #REF!, 0))=$A15, 1, 0)))), "")} | I15: {=IF($H15="", "", IF($H15=2, SUM(IF(INDEX(_xlfn._xlws.FILTER(#REF!,#REF!= I$5), 0, MATCH($Q$2,#REF!, 0))>1.9, 1, 0)), IF(SUM(IF(INDEX(_xlfn._xlws.FILTER(#REF!,#REF!= I$5), 0, MATCH($Q$2,#REF!, 0))=$H15, 1, 0))=0, "", SUM(IF(INDEX(_xlfn._xlws.FILTER(#REF!,#REF!= I$5), 0, MATCH($Q$2,#REF!, 0))=$H15, 1, 0)))))} | J15: {=IFERROR(IF(OR($H15="", J14=""), "", IF($H15=2, SUM(IF(INDEX(_xlfn._xlws.FILTER(#REF!,#REF!= J$5), 0, MATCH($Q$2,#REF!, 0))>1.9, 1, 0)), IF(SUM(IF(INDEX(_xlfn._xlws.FILTER(#REF!,#REF!= J$5), 0, MATCH($Q$2,#REF!, 0))=$H15, 1, 0))=0, "", SUM(IF(INDEX(_xlfn._xlws.FILTER(#REF!,#REF!= J$5), 0, MATCH($Q$2,#REF!, 0))=$H15, 1, 0))))), "")} | K15: {=IFERROR(IF(OR($H15="", K14=""), "", IF($H15=2, SUM(IF(INDEX(_xlfn._xlws.FILTER(#REF!,#REF!= K$5), 0, MATCH($Q$2,#REF!, 0))>1.9, 1, 0)), IF(SUM(IF(INDEX(_xlfn._xlws.FILTER(#REF!,#REF!= K$5), 0, MATCH($Q$2,#REF!, 0))=$H15, 1, 0))=0, "", SUM(IF(INDEX(_xlfn._xlws.FILTER(#REF!,#REF!= K$5), 0, MATCH($Q$2,#REF!, 0))=$H15, 1, 0))))), "")} | L15: {=IFERROR(IF(OR($H15="", L14=""), "", IF($H15=2, SUM(IF(INDEX(_xlfn._xlws.FILTER(#REF!,#REF!= L$5), 0, MATCH($Q$2,#REF!, 0))>1.9, 1, 0)), IF(SUM(IF(INDEX(_xlfn._xlws.FILTER(#REF!,#REF!= L$5), 0, MATCH($Q$2,#REF!, 0))=$H15, 1, 0))=0, "", SUM(IF(INDEX(_xlfn._xlws.FILTER(#REF!,#REF!= L$5), 0, MATCH($Q$2,#REF!, 0))=$H15, 1, 0))))), "")} | M15: {=IFERROR(IF(OR($H15="", M14=""), "", IF($H15=2, SUM(IF(INDEX(_xlfn._xlws.FILTER(#REF!,#REF!= M$5), 0, MATCH($Q$2,#REF!, 0))>1.9, 1, 0)), IF(SUM(IF(INDEX(_xlfn._xlws.FILTER(#REF!,#REF!= M$5), 0, MATCH($Q$2,#REF!, 0))=$H15, 1, 0))=0, "", SUM(IF(INDEX(_xlfn._xlws.FILTER(#REF!,#REF!= M$5), 0, MATCH($Q$2,#REF!, 0))=$H15, 1, 0))))), "")}
B16: {=IF($A16="", "", IF(SUM(IF(INDEX(_xlfn._xlws.FILTER(#REF!, tblPiNAnalysis[Population Group]=B$5), 0, MATCH(_xlfn.CONCAT($Q$2, "%"), #REF!, 0))=$A16, 1, 0))=0, "",SUM(IF(INDEX(_xlfn._xlws.FILTER(#REF!, tblPiNAnalysis[Population Group]=B$5), 0, MATCH(_xlfn.CONCAT($Q$2, "%"), #REF!, 0))=$A16, 1, 0))))} | C16: {=IFERROR(IF(OR($A16="", C$5=""), "", IF(SUM(IF(INDEX(_xlfn._xlws.FILTER(#REF!, tblPiNAnalysis[Population Group]=C$5), 0, MATCH(_xlfn.CONCAT($Q$2, "%"), #REF!, 0))=$A16, 1, 0))=0, "",SUM(IF(INDEX(_xlfn._xlws.FILTER(#REF!, tblPiNAnalysis[Population Group]=C$5), 0, MATCH(_xlfn.CONCAT($Q$2, "%"), #REF!, 0))=$A16, 1, 0)))), "")} | D16: {=IFERROR(IF(OR($A16="", D$5=""), "", IF(SUM(IF(INDEX(_xlfn._xlws.FILTER(#REF!, tblPiNAnalysis[Population Group]=D$5), 0, MATCH(_xlfn.CONCAT($Q$2, "%"), #REF!, 0))=$A16, 1, 0))=0, "",SUM(IF(INDEX(_xlfn._xlws.FILTER(#REF!, tblPiNAnalysis[Population Group]=D$5), 0, MATCH(_xlfn.CONCAT($Q$2, "%"), #REF!, 0))=$A16, 1, 0)))), "")} | E16: {=IFERROR(IF(OR($A16="", E$5=""), "", IF(SUM(IF(INDEX(_xlfn._xlws.FILTER(#REF!, tblPiNAnalysis[Population Group]=E$5), 0, MATCH(_xlfn.CONCAT($Q$2, "%"), #REF!, 0))=$A16, 1, 0))=0, "",SUM(IF(INDEX(_xlfn._xlws.FILTER(#REF!, tblPiNAnalysis[Population Group]=E$5), 0, MATCH(_xlfn.CONCAT($Q$2, "%"), #REF!, 0))=$A16, 1, 0)))), "")} | F16: {=IFERROR(IF(OR($A16="", F$5=""), "", IF(SUM(IF(INDEX(_xlfn._xlws.FILTER(#REF!, tblPiNAnalysis[CCCM]=F$5), 0, MATCH(_xlfn.CONCAT($Q$2, "%"), #REF!, 0))=$A16, 1, 0))=0, "",SUM(IF(INDEX(_xlfn._xlws.FILTER(#REF!, tblPiNAnalysis[CCCM]=F$5), 0, MATCH(_xlfn.CONCAT($Q$2, "%"), #REF!, 0))=$A16, 1, 0)))), "")} | I16: {=IF($H16="", "", IF($H16=2, SUM(IF(INDEX(_xlfn._xlws.FILTER(#REF!,#REF!= I$5), 0, MATCH($Q$2,#REF!, 0))>1.9, 1, 0)), IF(SUM(IF(INDEX(_xlfn._xlws.FILTER(#REF!,#REF!= I$5), 0, MATCH($Q$2,#REF!, 0))=$H16, 1, 0))=0, "", SUM(IF(INDEX(_xlfn._xlws.FILTER(#REF!,#REF!= I$5), 0, MATCH($Q$2,#REF!, 0))=$H16, 1, 0)))))} | J16: {=IFERROR(IF(OR($H16="", J15=""), "", IF($H16=2, SUM(IF(INDEX(_xlfn._xlws.FILTER(#REF!,#REF!= J$5), 0, MATCH($Q$2,#REF!, 0))>1.9, 1, 0)), IF(SUM(IF(INDEX(_xlfn._xlws.FILTER(#REF!,#REF!= J$5), 0, MATCH($Q$2,#REF!, 0))=$H16, 1, 0))=0, "", SUM(IF(INDEX(_xlfn._xlws.FILTER(#REF!,#REF!= J$5), 0, MATCH($Q$2,#REF!, 0))=$H16, 1, 0))))), "")} | K16: {=IFERROR(IF(OR($H16="", K15=""), "", IF($H16=2, SUM(IF(INDEX(_xlfn._xlws.FILTER(#REF!,#REF!= K$5), 0, MATCH($Q$2,#REF!, 0))>1.9, 1, 0)), IF(SUM(IF(INDEX(_xlfn._xlws.FILTER(#REF!,#REF!= K$5), 0, MATCH($Q$2,#REF!, 0))=$H16, 1, 0))=0, "", SUM(IF(INDEX(_xlfn._xlws.FILTER(#REF!,#REF!= K$5), 0, MATCH($Q$2,#REF!, 0))=$H16, 1, 0))))), "")} | L16: {=IFERROR(IF(OR($H16="", L15=""), "", IF($H16=2, SUM(IF(INDEX(_xlfn._xlws.FILTER(#REF!,#REF!= L$5), 0, MATCH($Q$2,#REF!, 0))>1.9, 1, 0)), IF(SUM(IF(INDEX(_xlfn._xlws.FILTER(#REF!,#REF!= L$5), 0, MATCH($Q$2,#REF!, 0))=$H16, 1, 0))=0, "", SUM(IF(INDEX(_xlfn._xlws.FILTER(#REF!,#REF!= L$5), 0, MATCH($Q$2,#REF!, 0))=$H16, 1, 0))))), "")} | M16: {=IFERROR(IF(OR($H16="", M15=""), "", IF($H16=2, SUM(IF(INDEX(_xlfn._xlws.FILTER(#REF!,#REF!= M$5), 0, MATCH($Q$2,#REF!, 0))>1.9, 1, 0)), IF(SUM(IF(INDEX(_xlfn._xlws.FILTER(#REF!,#REF!= M$5), 0, MATCH($Q$2,#REF!, 0))=$H16, 1, 0))=0, "", SUM(IF(INDEX(_xlfn._xlws.FILTER(#REF!,#REF!= M$5), 0, MATCH($Q$2,#REF!, 0))=$H16, 1, 0))))), "")}
B17: {=IF($A17="", "", IF(SUM(IF(INDEX(_xlfn._xlws.FILTER(#REF!, tblPiNAnalysis[Population Group]=B$5), 0, MATCH(_xlfn.CONCAT($Q$2, "%"), #REF!, 0))=$A17, 1, 0))=0, "",SUM(IF(INDEX(_xlfn._xlws.FILTER(#REF!, tblPiNAnalysis[Population Group]=B$5), 0, MATCH(_xlfn.CONCAT($Q$2, "%"), #REF!, 0))=$A17, 1, 0))))} | C17: {=IFERROR(IF(OR($A17="", C$5=""), "", IF(SUM(IF(INDEX(_xlfn._xlws.FILTER(#REF!, tblPiNAnalysis[Population Group]=C$5), 0, MATCH(_xlfn.CONCAT($Q$2, "%"), #REF!, 0))=$A17, 1, 0))=0, "",SUM(IF(INDEX(_xlfn._xlws.FILTER(#REF!, tblPiNAnalysis[Population Group]=C$5), 0, MATCH(_xlfn.CONCAT($Q$2, "%"), #REF!, 0))=$A17, 1, 0)))), "")} | D17: {=IFERROR(IF(OR($A17="", D$5=""), "", IF(SUM(IF(INDEX(_xlfn._xlws.FILTER(#REF!, tblPiNAnalysis[Population Group]=D$5), 0, MATCH(_xlfn.CONCAT($Q$2, "%"), #REF!, 0))=$A17, 1, 0))=0, "",SUM(IF(INDEX(_xlfn._xlws.FILTER(#REF!, tblPiNAnalysis[Population Group]=D$5), 0, MATCH(_xlfn.CONCAT($Q$2, "%"), #REF!, 0))=$A17, 1, 0)))), "")} | E17: {=IFERROR(IF(OR($A17="", E$5=""), "", IF(SUM(IF(INDEX(_xlfn._xlws.FILTER(#REF!, tblPiNAnalysis[Population Group]=E$5), 0, MATCH(_xlfn.CONCAT($Q$2, "%"), #REF!, 0))=$A17, 1, 0))=0, "",SUM(IF(INDEX(_xlfn._xlws.FILTER(#REF!, tblPiNAnalysis[Population Group]=E$5), 0, MATCH(_xlfn.CONCAT($Q$2, "%"), #REF!, 0))=$A17, 1, 0)))), "")} | F17: {=IFERROR(IF(OR($A17="", F$5=""), "", IF(SUM(IF(INDEX(_xlfn._xlws.FILTER(#REF!, tblPiNAnalysis[CCCM]=F$5), 0, MATCH(_xlfn.CONCAT($Q$2, "%"), #REF!, 0))=$A17, 1, 0))=0, "",SUM(IF(INDEX(_xlfn._xlws.FILTER(#REF!, tblPiNAnalysis[CCCM]=F$5), 0, MATCH(_xlfn.CONCAT($Q$2, "%"), #REF!, 0))=$A17, 1, 0)))), "")} | I17: {=IF($H17="", "", IF($H17=2, SUM(IF(INDEX(_xlfn._xlws.FILTER(#REF!,#REF!= I$5), 0, MATCH($Q$2,#REF!, 0))>1.9, 1, 0)), IF(SUM(IF(INDEX(_xlfn._xlws.FILTER(#REF!,#REF!= I$5), 0, MATCH($Q$2,#REF!, 0))=$H17, 1, 0))=0, "", SUM(IF(INDEX(_xlfn._xlws.FILTER(#REF!,#REF!= I$5), 0, MATCH($Q$2,#REF!, 0))=$H17, 1, 0)))))} | J17: {=IFERROR(IF(OR($H17="", J16=""), "", IF($H17=2, SUM(IF(INDEX(_xlfn._xlws.FILTER(#REF!,#REF!= J$5), 0, MATCH($Q$2,#REF!, 0))>1.9, 1, 0)), IF(SUM(IF(INDEX(_xlfn._xlws.FILTER(#REF!,#REF!= J$5), 0, MATCH($Q$2,#REF!, 0))=$H17, 1, 0))=0, "", SUM(IF(INDEX(_xlfn._xlws.FILTER(#REF!,#REF!= J$5), 0, MATCH($Q$2,#REF!, 0))=$H17, 1, 0))))), "")} | K17: {=IFERROR(IF(OR($H17="", K16=""), "", IF($H17=2, SUM(IF(INDEX(_xlfn._xlws.FILTER(#REF!,#REF!= K$5), 0, MATCH($Q$2,#REF!, 0))>1.9, 1, 0)), IF(SUM(IF(INDEX(_xlfn._xlws.FILTER(#REF!,#REF!= K$5), 0, MATCH($Q$2,#REF!, 0))=$H17, 1, 0))=0, "", SUM(IF(INDEX(_xlfn._xlws.FILTER(#REF!,#REF!= K$5), 0, MATCH($Q$2,#REF!, 0))=$H17, 1, 0))))), "")} | L17: {=IFERROR(IF(OR($H17="", L16=""), "", IF($H17=2, SUM(IF(INDEX(_xlfn._xlws.FILTER(#REF!,#REF!= L$5), 0, MATCH($Q$2,#REF!, 0))>1.9, 1, 0)), IF(SUM(IF(INDEX(_xlfn._xlws.FILTER(#REF!,#REF!= L$5), 0, MATCH($Q$2,#REF!, 0))=$H17, 1, 0))=0, "", SUM(IF(INDEX(_xlfn._xlws.FILTER(#REF!,#REF!= L$5), 0, MATCH($Q$2,#REF!, 0))=$H17, 1, 0))))), "")} | M17: {=IFERROR(IF(OR($H17="", M16=""), "", IF($H17=2, SUM(IF(INDEX(_xlfn._xlws.FILTER(#REF!,#REF!= M$5), 0, MATCH($Q$2,#REF!, 0))>1.9, 1, 0)), IF(SUM(IF(INDEX(_xlfn._xlws.FILTER(#REF!,#REF!= M$5), 0, MATCH($Q$2,#REF!, 0))=$H17, 1, 0))=0, "", SUM(IF(INDEX(_xlfn._xlws.FILTER(#REF!,#REF!= M$5), 0, MATCH($Q$2,#REF!, 0))=$H17, 1, 0))))), "")}
B18: {=IF($A18="", "", IF(SUM(IF(INDEX(_xlfn._xlws.FILTER(#REF!, tblPiNAnalysis[Population Group]=B$5), 0, MATCH(_xlfn.CONCAT($Q$2, "%"), #REF!, 0))=$A18, 1, 0))=0, "",SUM(IF(INDEX(_xlfn._xlws.FILTER(#REF!, tblPiNAnalysis[Population Group]=B$5), 0, MATCH(_xlfn.CONCAT($Q$2, "%"), #REF!, 0))=$A18, 1, 0))))} | C18: {=IFERROR(IF(OR($A18="", C$5=""), "", IF(SUM(IF(INDEX(_xlfn._xlws.FILTER(#REF!, tblPiNAnalysis[Population Group]=C$5), 0, MATCH(_xlfn.CONCAT($Q$2, "%"), #REF!, 0))=$A18, 1, 0))=0, "",SUM(IF(INDEX(_xlfn._xlws.FILTER(#REF!, tblPiNAnalysis[Population Group]=C$5), 0, MATCH(_xlfn.CONCAT($Q$2, "%"), #REF!, 0))=$A18, 1, 0)))), "")} | D18: {=IFERROR(IF(OR($A18="", D$5=""), "", IF(SUM(IF(INDEX(_xlfn._xlws.FILTER(#REF!, tblPiNAnalysis[Population Group]=D$5), 0, MATCH(_xlfn.CONCAT($Q$2, "%"), #REF!, 0))=$A18, 1, 0))=0, "",SUM(IF(INDEX(_xlfn._xlws.FILTER(#REF!, tblPiNAnalysis[Population Group]=D$5), 0, MATCH(_xlfn.CONCAT($Q$2, "%"), #REF!, 0))=$A18, 1, 0)))), "")} | E18: {=IFERROR(IF(OR($A18="", E$5=""), "", IF(SUM(IF(INDEX(_xlfn._xlws.FILTER(#REF!, tblPiNAnalysis[Population Group]=E$5), 0, MATCH(_xlfn.CONCAT($Q$2, "%"), #REF!, 0))=$A18, 1, 0))=0, "",SUM(IF(INDEX(_xlfn._xlws.FILTER(#REF!, tblPiNAnalysis[Population Group]=E$5), 0, MATCH(_xlfn.CONCAT($Q$2, "%"), #REF!, 0))=$A18, 1, 0)))), "")} | F18: {=IFERROR(IF(OR($A18="", F$5=""), "", IF(SUM(IF(INDEX(_xlfn._xlws.FILTER(#REF!, tblPiNAnalysis[CCCM]=F$5), 0, MATCH(_xlfn.CONCAT($Q$2, "%"), #REF!, 0))=$A18, 1, 0))=0, "",SUM(IF(INDEX(_xlfn._xlws.FILTER(#REF!, tblPiNAnalysis[CCCM]=F$5), 0, MATCH(_xlfn.CONCAT($Q$2, "%"), #REF!, 0))=$A18, 1, 0)))), "")} | I18: {=IF($H18="", "", IF($H18=2, SUM(IF(INDEX(_xlfn._xlws.FILTER(#REF!,#REF!= I$5), 0, MATCH($Q$2,#REF!, 0))>1.9, 1, 0)), IF(SUM(IF(INDEX(_xlfn._xlws.FILTER(#REF!,#REF!= I$5), 0, MATCH($Q$2,#REF!, 0))=$H18, 1, 0))=0, "", SUM(IF(INDEX(_xlfn._xlws.FILTER(#REF!,#REF!= I$5), 0, MATCH($Q$2,#REF!, 0))=$H18, 1, 0)))))} | J18: {=IFERROR(IF(OR($H18="", J17=""), "", IF($H18=2, SUM(IF(INDEX(_xlfn._xlws.FILTER(#REF!,#REF!= J$5), 0, MATCH($Q$2,#REF!, 0))>1.9, 1, 0)), IF(SUM(IF(INDEX(_xlfn._xlws.FILTER(#REF!,#REF!= J$5), 0, MATCH($Q$2,#REF!, 0))=$H18, 1, 0))=0, "", SUM(IF(INDEX(_xlfn._xlws.FILTER(#REF!,#REF!= J$5), 0, MATCH($Q$2,#REF!, 0))=$H18, 1, 0))))), "")} | K18: {=IFERROR(IF(OR($H18="", K17=""), "", IF($H18=2, SUM(IF(INDEX(_xlfn._xlws.FILTER(#REF!,#REF!= K$5), 0, MATCH($Q$2,#REF!, 0))>1.9, 1, 0)), IF(SUM(IF(INDEX(_xlfn._xlws.FILTER(#REF!,#REF!= K$5), 0, MATCH($Q$2,#REF!, 0))=$H18, 1, 0))=0, "", SUM(IF(INDEX(_xlfn._xlws.FILTER(#REF!,#REF!= K$5), 0, MATCH($Q$2,#REF!, 0))=$H18, 1, 0))))), "")} | L18: {=IFERROR(IF(OR($H18="", L17=""), "", IF($H18=2, SUM(IF(INDEX(_xlfn._xlws.FILTER(#REF!,#REF!= L$5), 0, MATCH($Q$2,#REF!, 0))>1.9, 1, 0)), IF(SUM(IF(INDEX(_xlfn._xlws.FILTER(#REF!,#REF!= L$5), 0, MATCH($Q$2,#REF!, 0))=$H18, 1, 0))=0, "", SUM(IF(INDEX(_xlfn._xlws.FILTER(#REF!,#REF!= L$5), 0, MATCH($Q$2,#REF!, 0))=$H18, 1, 0))))), "")} | M18: {=IFERROR(IF(OR($H18="", M17=""), "", IF($H18=2, SUM(IF(INDEX(_xlfn._xlws.FILTER(#REF!,#REF!= M$5), 0, MATCH($Q$2,#REF!, 0))>1.9, 1, 0)), IF(SUM(IF(INDEX(_xlfn._xlws.FILTER(#REF!,#REF!= M$5), 0, MATCH($Q$2,#REF!, 0))=$H18, 1, 0))=0, "", SUM(IF(INDEX(_xlfn._xlws.FILTER(#REF!,#REF!= M$5), 0, MATCH($Q$2,#REF!, 0))=$H18, 1, 0))))), "")}
... B27: {=IF($A27="", "", IF(SUM(IF(INDEX(_xlfn._xlws.FILTER(#REF!, tblPiNAnalysis[Population Group]=B$5), 0, MATCH(_xlfn.CONCAT($Q$2, "%"), #REF!, 0))=$A27, 1, 0))=0, "",SUM(IF(INDEX(_xlfn._xlws.FILTER(#REF!, tblPiNAnalysis[Population Group]=B$5), 0, MATCH(_xlfn.CONCAT($Q$2, "%"), #REF!, 0))=$A27, 1, 0))))} | C27: {=IFERROR(IF(OR($A27="", C$5=""), "", IF(SUM(IF(INDEX(_xlfn._xlws.FILTER(#REF!, tblPiNAnalysis[Population Group]=C$5), 0, MATCH(_xlfn.CONCAT($Q$2, "%"), #REF!, 0))=$A27, 1, 0))=0, "",SUM(IF(INDEX(_xlfn._xlws.FILTER(#REF!, tblPiNAnalysis[Population Group]=C$5), 0, MATCH(_xlfn.CONCAT($Q$2, "%"), #REF!, 0))=$A27, 1, 0)))), "")} | D27: {=IFERROR(IF(OR($A27="", D$5=""), "", IF(SUM(IF(INDEX(_xlfn._xlws.FILTER(#REF!, tblPiNAnalysis[Population Group]=D$5), 0, MATCH(_xlfn.CONCAT($Q$2, "%"), #REF!, 0))=$A27, 1, 0))=0, "",SUM(IF(INDEX(_xlfn._xlws.FILTER(#REF!, tblPiNAnalysis[Population Group]=D$5), 0, MATCH(_xlfn.CONCAT($Q$2, "%"), #REF!, 0))=$A27, 1, 0)))), "")} | E27: {=IFERROR(IF(OR($A27="", E$5=""), "", IF(SUM(IF(INDEX(_xlfn._xlws.FILTER(#REF!, tblPiNAnalysis[Population Group]=E$5), 0, MATCH(_xlfn.CONCAT($Q$2, "%"), #REF!, 0))=$A27, 1, 0))=0, "",SUM(IF(INDEX(_xlfn._xlws.FILTER(#REF!, tblPiNAnalysis[Population Group]=E$5), 0, MATCH(_xlfn.CONCAT($Q$2, "%"), #REF!, 0))=$A27, 1, 0)))), "")} | F27: {=IFERROR(IF(OR($A27="", F$5=""), "", IF(SUM(IF(INDEX(_xlfn._xlws.FILTER(#REF!, tblPiNAnalysis[CCCM]=F$5), 0, MATCH(_xlfn.CONCAT($Q$2, "%"), #REF!, 0))=$A27, 1, 0))=0, "",SUM(IF(INDEX(_xlfn._xlws.FILTER(#REF!, tblPiNAnalysis[CCCM]=F$5), 0, MATCH(_xlfn.CONCAT($Q$2, "%"), #REF!, 0))=$A27, 1, 0)))), "")} | I27: {=IF($H27="", "", IF($H27=2, SUM(IF(INDEX(_xlfn._xlws.FILTER(#REF!,#REF!= I$5), 0, MATCH($Q$2,#REF!, 0))>1.9, 1, 0)), IF(SUM(IF(INDEX(_xlfn._xlws.FILTER(#REF!,#REF!= I$5), 0, MATCH($Q$2,#REF!, 0))=$H27, 1, 0))=0, "", SUM(IF(INDEX(_xlfn._xlws.FILTER(#REF!,#REF!= I$5), 0, MATCH($Q$2,#REF!, 0))=$H27, 1, 0)))))} | J27: {=IFERROR(IF(OR($H27="", J26=""), "", IF($H27=2, SUM(IF(INDEX(_xlfn._xlws.FILTER(#REF!,#REF!= J$5), 0, MATCH($Q$2,#REF!, 0))>1.9, 1, 0)), IF(SUM(IF(INDEX(_xlfn._xlws.FILTER(#REF!,#REF!= J$5), 0, MATCH($Q$2,#REF!, 0))=$H27, 1, 0))=0, "", SUM(IF(INDEX(_xlfn._xlws.FILTER(#REF!,#REF!= J$5), 0, MATCH($Q$2,#REF!, 0))=$H27, 1, 0))))), "")} | K27: {=IFERROR(IF(OR($H27="", K26=""), "", IF($H27=2, SUM(IF(INDEX(_xlfn._xlws.FILTER(#REF!,#REF!= K$5), 0, MATCH($Q$2,#REF!, 0))>1.9, 1, 0)), IF(SUM(IF(INDEX(_xlfn._xlws.FILTER(#REF!,#REF!= K$5), 0, MATCH($Q$2,#REF!, 0))=$H27, 1, 0))=0, "", SUM(IF(INDEX(_xlfn._xlws.FILTER(#REF!,#REF!= K$5), 0, MATCH($Q$2,#REF!, 0))=$H27, 1, 0))))), "")} | L27: {=IFERROR(IF(OR($H27="", L26=""), "", IF($H27=2, SUM(IF(INDEX(_xlfn._xlws.FILTER(#REF!,#REF!= L$5), 0, MATCH($Q$2,#REF!, 0))>1.9, 1, 0)), IF(SUM(IF(INDEX(_xlfn._xlws.FILTER(#REF!,#REF!= L$5), 0, MATCH($Q$2,#REF!, 0))=$H27, 1, 0))=0, "", SUM(IF(INDEX(_xlfn._xlws.FILTER(#REF!,#REF!= L$5), 0, MATCH($Q$2,#REF!, 0))=$H27, 1, 0))))), "")} | M27: {=IFERROR(IF(OR($H27="", M26=""), "", IF($H27=2, SUM(IF(INDEX(_xlfn._xlws.FILTER(#REF!,#REF!= M$5), 0, MATCH($Q$2,#REF!, 0))>1.9, 1, 0)), IF(SUM(IF(INDEX(_xlfn._xlws.FILTER(#REF!,#REF!= M$5), 0, MATCH($Q$2,#REF!, 0))=$H27, 1, 0))=0, "", SUM(IF(INDEX(_xlfn._xlws.FILTER(#REF!,#REF!= M$5), 0, MATCH($Q$2,#REF!, 0))=$H27, 1, 0))))), "")}
B28: {=IF($A28="", "", IF(SUM(IF(INDEX(_xlfn._xlws.FILTER(#REF!, tblPiNAnalysis[Population Group]=B$5), 0, MATCH(_xlfn.CONCAT($Q$2, "%"), #REF!, 0))=$A28, 1, 0))=0, "",SUM(IF(INDEX(_xlfn._xlws.FILTER(#REF!, tblPiNAnalysis[Population Group]=B$5), 0, MATCH(_xlfn.CONCAT($Q$2, "%"), #REF!, 0))=$A28, 1, 0))))} | C28: {=IFERROR(IF(OR($A28="", C$5=""), "", IF(SUM(IF(INDEX(_xlfn._xlws.FILTER(#REF!, tblPiNAnalysis[Population Group]=C$5), 0, MATCH(_xlfn.CONCAT($Q$2, "%"), #REF!, 0))=$A28, 1, 0))=0, "",SUM(IF(INDEX(_xlfn._xlws.FILTER(#REF!, tblPiNAnalysis[Population Group]=C$5), 0, MATCH(_xlfn.CONCAT($Q$2, "%"), #REF!, 0))=$A28, 1, 0)))), "")} | D28: {=IFERROR(IF(OR($A28="", D$5=""), "", IF(SUM(IF(INDEX(_xlfn._xlws.FILTER(#REF!, tblPiNAnalysis[Population Group]=D$5), 0, MATCH(_xlfn.CONCAT($Q$2, "%"), #REF!, 0))=$A28, 1, 0))=0, "",SUM(IF(INDEX(_xlfn._xlws.FILTER(#REF!, tblPiNAnalysis[Population Group]=D$5), 0, MATCH(_xlfn.CONCAT($Q$2, "%"), #REF!, 0))=$A28, 1, 0)))), "")} | E28: {=IFERROR(IF(OR($A28="", E$5=""), "", IF(SUM(IF(INDEX(_xlfn._xlws.FILTER(#REF!, tblPiNAnalysis[Population Group]=E$5), 0, MATCH(_xlfn.CONCAT($Q$2, "%"), #REF!, 0))=$A28, 1, 0))=0, "",SUM(IF(INDEX(_xlfn._xlws.FILTER(#REF!, tblPiNAnalysis[Population Group]=E$5), 0, MATCH(_xlfn.CONCAT($Q$2, "%"), #REF!, 0))=$A28, 1, 0)))), "")} | F28: {=IFERROR(IF(OR($A28="", F$5=""), "", IF(SUM(IF(INDEX(_xlfn._xlws.FILTER(#REF!, tblPiNAnalysis[CCCM]=F$5), 0, MATCH(_xlfn.CONCAT($Q$2, "%"), #REF!, 0))=$A28, 1, 0))=0, "",SUM(IF(INDEX(_xlfn._xlws.FILTER(#REF!, tblPiNAnalysis[CCCM]=F$5), 0, MATCH(_xlfn.CONCAT($Q$2, "%"), #REF!, 0))=$A28, 1, 0)))), "")} | I28: {=IF($H28="", "", IF($H28=2, SUM(IF(INDEX(_xlfn._xlws.FILTER(#REF!,#REF!= I$5), 0, MATCH($Q$2,#REF!, 0))>1.9, 1, 0)), IF(SUM(IF(INDEX(_xlfn._xlws.FILTER(#REF!,#REF!= I$5), 0, MATCH($Q$2,#REF!, 0))=$H28, 1, 0))=0, "", SUM(IF(INDEX(_xlfn._xlws.FILTER(#REF!,#REF!= I$5), 0, MATCH($Q$2,#REF!, 0))=$H28, 1, 0)))))} | J28: {=IFERROR(IF(OR($H28="", J27=""), "", IF($H28=2, SUM(IF(INDEX(_xlfn._xlws.FILTER(#REF!,#REF!= J$5), 0, MATCH($Q$2,#REF!, 0))>1.9, 1, 0)), IF(SUM(IF(INDEX(_xlfn._xlws.FILTER(#REF!,#REF!= J$5), 0, MATCH($Q$2,#REF!, 0))=$H28, 1, 0))=0, "", SUM(IF(INDEX(_xlfn._xlws.FILTER(#REF!,#REF!= J$5), 0, MATCH($Q$2,#REF!, 0))=$H28, 1, 0))))), "")} | K28: {=IFERROR(IF(OR($H28="", K27=""), "", IF($H28=2, SUM(IF(INDEX(_xlfn._xlws.FILTER(#REF!,#REF!= K$5), 0, MATCH($Q$2,#REF!, 0))>1.9, 1, 0)), IF(SUM(IF(INDEX(_xlfn._xlws.FILTER(#REF!,#REF!= K$5), 0, MATCH($Q$2,#REF!, 0))=$H28, 1, 0))=0, "", SUM(IF(INDEX(_xlfn._xlws.FILTER(#REF!,#REF!= K$5), 0, MATCH($Q$2,#REF!, 0))=$H28, 1, 0))))), "")} | L28: {=IFERROR(IF(OR($H28="", L27=""), "", IF($H28=2, SUM(IF(INDEX(_xlfn._xlws.FILTER(#REF!,#REF!= L$5), 0, MATCH($Q$2,#REF!, 0))>1.9, 1, 0)), IF(SUM(IF(INDEX(_xlfn._xlws.FILTER(#REF!,#REF!= L$5), 0, MATCH($Q$2,#REF!, 0))=$H28, 1, 0))=0, "", SUM(IF(INDEX(_xlfn._xlws.FILTER(#REF!,#REF!= L$5), 0, MATCH($Q$2,#REF!, 0))=$H28, 1, 0))))), "")} | M28: {=IFERROR(IF(OR($H28="", M27=""), "", IF($H28=2, SUM(IF(INDEX(_xlfn._xlws.FILTER(#REF!,#REF!= M$5), 0, MATCH($Q$2,#REF!, 0))>1.9, 1, 0)), IF(SUM(IF(INDEX(_xlfn._xlws.FILTER(#REF!,#REF!= M$5), 0, MATCH($Q$2,#REF!, 0))=$H28, 1, 0))=0, "", SUM(IF(INDEX(_xlfn._xlws.FILTER(#REF!,#REF!= M$5), 0, MATCH($Q$2,#REF!, 0))=$H28, 1, 0))))), "")} | Q28: Notes: | AB28: Notes:
